Workbook

Sheet 全馬データ
A1: 開催日 | B1: 場 | C1: R | D1: 馬番 | E1: 馬名 | F1: Eval馬券内率(%) | G1: Eval順位 | H1: 着順 | I1: 3着内 | J1: 複勝払戻(円) | K1: 最終複勝オッズ下限 | L1: 最終複勝オッズ上限 | M1: 備考
A2: 46228 | B2: 新潟 | C2: 1 | D2: 1 | E2: コスモバルムンク | F2: 34 | G2: 4 | H2: 4 | I2: {=IF(A2:A16977="","",IF(ISNUMBER(H2:H16977),IF(H2:H16977<=3,"○","×"),""))} -> × | M2: 画像OCR＋目視補正／着順4=4着以下
A3: 46228 | B3: 新潟 | C3: 1 | D3: 2 | E3: フルーツバスケット | F3: 31 | G3: 5 | H3: 2 | I3: ○ | J3: 120 | M3: 画像OCR＋目視補正／着順4=4着以下
A4: 46228 | B4: 新潟 | C4: 1 | D4: 3 | E4: ソラニワラエバ | F4: 31 | G4: 5 | H4: 4 | I4: × | M4: 画像OCR＋目視補正／着順4=4着以下
A5: 46228 | B5: 新潟 | C5: 1 | D5: 4 | E5: コルサロ | F5: 37 | G5: 3 | H5: 4 | I5: × | M5: 画像OCR＋目視補正／着順4=4着以下
A6: 46228 | B6: 新潟 | C6: 1 | D6: 5 | E6: トリプティーク | F6: 6 | G6: 10 | H6: 4 | I6: × | M6: 画像OCR＋目視補正／着順4=4着以下
A7: 46228 | B7: 新潟 | C7: 1 | D7: 6 | E7: ローグアン | F7: 13 | G7: 8 | H7: 4 | I7: × | M7: 画像OCR＋目視補正／着順4=4着以下
A8: 46228 | B8: 新潟 | C8: 1 | D8: 7 | E8: ノシェリー | F8: 44 | G8: 2 | H8: 3 | I8: ○ | J8: 130 | M8: 画像OCR＋目視補正／着順4=4着以下
A9: 46228 | B9: 新潟 | C9: 1 | D9: 8 | E9: ランドジャイアンツ | F9: 29 | G9: 7 | H9: 4 | I9: × | M9: 画像OCR＋目視補正／着順4=4着以下
A10: 46228 | B10: 新潟 | C10: 1 | D10: 9 | E10: ワンコール | F10: 10 | G10: 9 | H10: 4 | I10: × | M10: 画像OCR＋目視補正／着順4=4着以下
A11: 46228 | B11: 新潟 | C11: 1 | D11: 10 | E11: レゾルーティオ | F11: 60 | G11: 1 | H11: 1 | I11: ○ | J11: 110 | M11: 画像OCR＋目視補正／着順4=4着以下
A12: 46228 | B12: 新潟 | C12: 2 | D12: 1 | E12: エレクトス | F12: 31 | G12: 3 | H12: 4 | I12: × | M12: 画像OCR＋目視補正／着順4=4着以下
A13: 46228 | B13: 新潟 | C13: 2 | D13: 2 | E13: リコルディオーロ | F13: 31 | G13: 3 | H13: 4 | I13: × | M13: 画像OCR＋目視補正／着順4=4着以下
A14: 46228 | B14: 新潟 | C14: 2 | D14: 3 | E14: モミスケ | F14: 14 | G14: 10 | H14: 4 | I14: × | M14: 画像OCR＋目視補正／着順4=4着以下
A15: 46228 | B15: 新潟 | C15: 2 | D15: 4 | E15: ピウモッソ | F15: 37 | G15: 1 | H15: 4 | I15: × | M15: 画像OCR＋目視補正／着順4=4着以下
A16: 46228 | B16: 新潟 | C16: 2 | D16: 5 | E16: ランズエンド | F16: 27 | G16: 7 | H16: 4 | I16: × | M16: 画像OCR＋目視補正／着順4=4着以下
A17: 46228 | B17: 新潟 | C17: 2 | D17: 6 | E17: ユイチャンファイト | F17: 14 | G17: 10 | H17: 4 | I17: × | M17: 画像OCR＋目視補正／着順4=4着以下
A18: 46228 | B18: 新潟 | C18: 2 | D18: 7 | E18: サザンキンレンカ | F18: 27 | G18: 7 | H18: 4 | I18: × | M18: 画像OCR＋目視補正／着順4=4着以下
A19: 46228 | B19: 新潟 | C19: 2 | D19: 8 | E19: アレックスケー | F19: 31 | G19: 3 | H19: 3 | I19: ○ | J19: 370 | M19: 画像OCR＋目視補正／着順4=4着以下
A20: 46228 | B20: 新潟 | C20: 2 | D20: 9 | E20: スクワミッシュ | F20: 37 | G20: 1 | H20: 4 | I20: × | M20: 画像OCR＋目視補正／着順4=4着以下
A21: 46228 | B21: 新潟 | C21: 2 | D21: 10 | E21: ライヴバーボン | F21: 14 | G21: 10 | H21: 4 | I21: × | M21: 画像OCR＋目視補正／着順4=4着以下
A22: 46228 | B22: 新潟 | C22: 2 | D22: 11 | E22: イニシャルポイント | F22: 6 | G22: 14 | H22: 2 | I22: ○ | J22: 180 | M22: 画像OCR＋目視補正／着順4=4着以下
A23: 46228 | B23: 新潟 | C23: 2 | D23: 12 | E23: ミカミッチー | F23: 16 | G23: 9 | H23: 1 | I23: ○ | J23: 560 | M23: 画像OCR＋目視補正／着順4=4着以下
A24: 46228 | B24: 新潟 | C24: 2 | D24: 13 | E24: オンアロール | F24: 31 | G24: 3 | H24: 4 | I24: × | M24: 画像OCR＋目視補正／着順4=4着以下
A25: 46228 | B25: 新潟 | C25: 2 | D25: 14 | E25: コパノフラメンコ | F25: 12 | G25: 13 | H25: 4 | I25: × | M25: 画像OCR＋目視補正／着順4=4着以下
A26: 46228 | B26: 新潟 | C26: 3 | D26: 1 | E26: トルタパスカリーナ | F26: 37 | G26: 1 | H26: 2 | I26: ○ | J26: 110 | M26: 画像OCR＋目視補正／着順4=4着以下
A27: 46228 | B27: 新潟 | C27: 3 | D27: 2 | E27: リーペベラーリア | F27: 24 | G27: 4 | H27: 4 | I27: × | M27: 画像OCR＋目視補正／着順4=4着以下
A28: 46228 | B28: 新潟 | C28: 3 | D28: 3 | E28: スターマイン | F28: 27 | G28: 3 | H28: 4 | I28: × | M28: 画像OCR＋目視補正／着順4=4着以下
A29: 46228 | B29: 新潟 | C29: 3 | D29: 4 | E29: セプタードアイル | F29: 31 | G29: 2 | H29: 1 | I29: ○ | J29: 190 | M29: 画像OCR＋目視補正／着順4=4着以下
A30: 46228 | B30: 新潟 | C30: 3 | D30: 5 | E30: サトノスプレマシ | F30: 21 | G30: 6 | H30: 4 | I30: × | M30: 画像OCR＋目視補正／着順4=4着以下
A31: 46228 | B31: 新潟 | C31: 3 | D31: 6 | E31: スイートアリッサム | F31: 6 | G31: 8 | H31: 4 | I31: × | M31: 画像OCR＋目視補正／着順4=4着以下
A32: 46228 | B32: 新潟 | C32: 3 | D32: 7 | E32: プレママドンナ | F32: 21 | G32: 6 | H32: 4 | I32: × | M32: 画像OCR＋目視補正／着順4=4着以下
A33: 46228 | B33: 新潟 | C33: 3 | D33: 8 | E33: マリアンデール | F33: 24 | G33: 4 | H33: 3 | I33: ○ | J33: 270 | M33: 画像OCR＋目視補正／着順4=4着以下
A34: 46228 | B34: 新潟 | C34: 4 | D34: 1 | E34: サンマルオブウォ | F34: 4 | G34: 9 | H34: 4 | I34: × | M34: 画像OCR＋目視補正／着順4=4着以下
A35: 46228 | B35: 新潟 | C35: 4 | D35: 2 | E35: パチクリベスクリ | F35: 4 | G35: 9 | H35: 4 | I35: × | M35: 画像OCR＋目視補正／着順4=4着以下
A36: 46228 | B36: 新潟 | C36: 4 | D36: 3 | E36: プリプリプリン | F36: 44 | G36: 2 | H36: 1 | I36: ○ | J36: 140 | M36: 画像OCR＋目視補正／着順4=4着以下
A37: 46228 | B37: 新潟 | C37: 4 | D37: 4 | E37: スノーランス | F37: 37 | G37: 5 | H37: 3 | I37: ○ | J37: 180 | M37: 画像OCR＋目視補正／着順4=4着以下
A38: 46228 | B38: 新潟 | C38: 4 | D38: 5 | E38: シャインネージュニ | F38: 2 | G38: 14 | H38: 4 | I38: × | M38: 画像OCR＋目視補正／着順4=4着以下
A39: 46228 | B39: 新潟 | C39: 4 | D39: 6 | E39: ナーシリーヤ | F39: 8 | G39: 8 | H39: 4 | I39: × | M39: 画像OCR＋目視補正／着順4=4着以下
A40: 46228 | B40: 新潟 | C40: 4 | D40: 7 | E40: セイウンヤオヨロズ | F40: 41 | G40: 4 | H40: 4 | I40: × | M40: 画像OCR＋目視補正／着順4=4着以下
...

Sheet レース分析
A1: 開催日 | B1: 場 | C1: R | D1: 頭数 | E1: 1位馬番 | F1: 1位馬名 | G1: 1位率 | H1: 2位馬番 | I1: 2位馬名 | J1: 2位率 | K1: 3位馬番 | L1: 3位馬名 | M1: 3位率 | N1: 1位-2位差 | O1: 2位-3位差 | P1: 上位2頭合計 | Q1: 高信頼複勝 | R1: 独走複勝 | S1: 上位2頭ワイド | T1: 1位着順 | U1: 2位着順 | V1: 1-2ワイド | W1: 1位複勝払戻 | X1: ワイド払戻 | Y1: データ区分 | Z1: 備考 | AA1: 超高Eval | AB1: Eval80標準 | AC1: Eval80中差 | AD1: Eval80突出 | AE1: 70台突出 | AF1: 上位集中型 | AG1: 1位-3位断層型 | AH1: 少頭数高Eval | AI1: 1位-3位差 | AJ1: 1位Eval帯 | AK1: 1位-2位差帯 | AL1: 1位-3位差帯 | AM1: 上位2頭合計帯 | AN1: 頭数帯 | AO1: 1位最終複勝オッズ下限 | AP1: 1位複勝オッズ帯 | AQ1: レース属性 | AR1: race_name | AS1: race_type_code | AT1: race_type_label | AU1: race_condition_code | AV1: class_label | AW1: grade_code | AX1: grade_label | AY1: track_type | AZ1: track_label | BA1: distance | BB1: track_condition_code | BC1: track_condition_label | BD1: race_symbol_code | BE1: sex_condition_label | BF1: is_filly_only | BG1: weight_condition_code | BH1: weight_condition_label | BI1: declared_field_size | BJ1: turn_direction_code | BK1: turn_direction_label | BL1: inner_outer_code | BM1: inner_outer_label | BN1: course_code | BO1: course_label | BP1: event_region_code | BQ1: JRDB年齢条件 | BR1: JRDB距離帯 | BS1: JRDBグレード分類 | BT1: JRDB頭数照合 | BU1: JRDB性別条件
A2: 46228 | B2: 新潟 | C2: 1 | D2: 10 | E2: 10 | F2: レゾルーティオ | G2: 60 | H2: 7 | I2: ノシェリー | J2: 44 | K2: 4 | L2: コルサロ | M2: 37 | N2: =IF(A2="","",G2-J2) -> 16 | O2: =IF(A2="","",J2-M2) -> 7 | P2: =IF(A2="","",G2+J2) -> 104 | Q2: =IF(A2="","",IF(AND(Y2<>"参考",G2>=ルール設定!$B$2),"○","")) | R2: =IF(A2="","",IF(AND(Y2<>"参考",G2>=ルール設定!$B$3,N2>=ルール設定!$B$4),"○","")) | S2: =IF(A2="","",IF(AND(Y2<>"参考",G2>=ルール設定!$B$5,J2>=ルール設定!$B$6,O2>=ルール設定!$B$7),"○","")) | T2: 1 | U2: 3 | V2: =IF(A2="","",IF(AND(ISNUMBER(T2),ISNUMBER(U2)),IF(AND(T2<=3,U2<=3),"○","×"),"")) -> ○ | W2: 110 | X2: 260 | Y2: 事後発見 | AA2: {=IF(A2:A1146="","",IF((Y2:Y1146<>"参考")*(G2:G1146>=ルール設定!$B$10),"○",""))} | AB2: {=IF(A2:A1146="","",IF((Y2:Y1146<>"参考")*(G2:G1146>=ルール設定!$B$2)*(D2:D1146>=ルール設定!$B$11),"○",""))} | AC2: {=IF(A2:A1146="","",IF((Y2:Y1146<>"参考")*(G2:G1146>=ルール設定!$B$2)*(N2:N1146>=ルール設定!$B$12)*(N2:N1146<=ルール設定!$B$13),"○",""))} | AD2: {=IF(A2:A1146="","",IF((Y2:Y1146<>"参考")*(G2:G1146>=ルール設定!$B$2)*(N2:N1146>=ルール設定!$B$14),"○",""))} | AE2: {=IF(A2:A1146="","",IF((Y2:Y1146<>"参考")*(G2:G1146>=ルール設定!$B$15)*(G2:G1146<=ルール設定!$B$16)*(N2:N1146>=ルール設定!$B$14),"○",""))} | AF2: {=IF(A2:A1146="","",IF((Y2:Y1146<>"参考")*(G2:G1146>=ルール設定!$B$2)*(P2:P1146>=ルール設定!$B$17),"○",""))} | AG2: {=IF(A2:A1146="","",IF((Y2:Y1146<>"参考")*(G2:G1146>=ルール設定!$B$2)*(AI2:AI1146>=ルール設定!$B$18),"○",""))} | AH2: {=IF(A2:A1146="","",IF((Y2:Y1146<>"参考")*(G2:G1146>=ルール設定!$B$2)*(D2:D1146>=1)*(D2:D1146<=ルール設定!$B$19),"○",""))} | AI2: {=IF(A2:A1146="","",IF((ISNUMBER(G2:G1146))*(ISNUMBER(M2:M1146)),G2:G1146-M2:M1146,""))} -> 23 | AJ2: {=IF(A2:A1146="","",IF(NOT(ISNUMBER(G2:G1146)),"",IF(G2:G1146<=59,"～59",IF(G2:G1146<=69,"60～69",IF(G2:G1146<=74,"70～74",IF(G2:G1146<=79,"75～79",IF(G2:G1146<=84,"80～84","85以上")))))))} -> 60～69 | AK2: {=IF(A2:A1146="","",IF(NOT(ISNUMBER(N2:N1146)),"",IF(N2:N1146<=4,"0～4",IF(N2:N1146<=9,"5～9",IF(N2:N1146<=19,"10～19",IF(N2:N1146<=29,"20～29","30以上"))))))} -> 10～19 | AL2: {=IF(A2:A1146="","",IF(NOT(ISNUMBER(AI2:AI1146)),"",IF(AI2:AI1146<=9,"0～9",IF(AI2:AI1146<=19,"10～19",IF(AI2:AI1146<=29,"20～29",IF(AI2:AI1146<=39,"30～39","40以上"))))))} -> 20～29 | AM2: {=IF(A2:A1146="","",IF(NOT(ISNUMBER(P2:P1146)),"",IF(P2:P1146<=99,"～99",IF(P2:P1146<=119,"100～119",IF(P2:P1146<=139,"120～139",IF(P2:P1146<=159,"140～159","160以上"))))))} -> 100～119 | AN2: {=IF(A2:A1146="","",IF((NOT(ISNUMBER(D2:D1146)))+(D2:D1146<1),"",IF(D2:D1146<=7,"7以下",IF(D2:D1146<=11,"8～11",IF(D2:D1146<=14,"12～14","15以上")))))} -> 8～11 | AO2: =IF(A2="","",IF(COUNTIFS(全馬データ!$A$2:$A$50000,A2,全馬データ!$B$2:$B$50000,B2,全馬データ!$C$2:$C$50000,C2,全馬データ!$D$2:$D$50000,E2,全馬データ!$K$2:$K$50000,"<>")=0,"",SUMIFS(全馬データ!$K$2:$K$50000,全馬データ!$A$2:$A$50000,A2,全馬データ!$B$2:$B$50000,B2,全馬データ!$C$2:$C$50000,C2,全馬データ!$D$2:$D$50000,E2))) | AP2: =IF(A2="","",IF(AO2="","欠損",IF(AO2<=1.1,"1.0～1.1",IF(AO2<1.3,"1.2",IF(AO2<1.5,"1.3～1.4",IF(AO2<2,"1.5～1.9","2.0以上")))))) -> 欠損 | AQ2: =IF(A2="","",IF(ISNUMBER(SEARCH("2歳",Z2)),"2歳戦",IF(ISNUMBER(SEARCH("3歳未勝利",Z2)),"3歳未勝利",IF(ISNUMBER(SEARCH("未勝利",Z2)),"その他未勝利",IF(ISNUMBER(SEARCH("G1",Z2)),"G1",IF(ISNUMBER(SEARCH("G2",Z2)),"G2",IF(ISNUMBER(SEARCH("G3",Z2)),"G3",IF(ISNUMBER(SEARCH("古馬条件",Z2)),"古馬条件戦",IF(ISNUMBER(SEARCH("重賞",Z2)),"重賞","分類不能"))))))))) -> 分類不能 | AS2: 11 | AT2: 2歳 | AU2: A3 | AV2: 未勝利 | AY2: 1 | AZ2: 芝 | BA2: 1800 | BB2: 11 | BC2: 良 | BD2: 102 | BE2: 指定なし | BF2: 0 | BG2: 3 | BH2: 馬齢 | BI2: 10 | BJ2: 2 | BK2: 左 | BL2: 2 | BM2: 外 | BN2: 1 | BO2: A | BP2: 1 | BQ2: =IF(A2="","",AT2) -> 2歳 | BR2: =IF(A2="","",IF(BA2<=1200,"～1200",IF(BA2<=1500,"1300～1500",IF(BA2=1600,"1600",IF(BA2<=1800,"1700～1800",IF(BA2<=2000,"1900～2000","2100以上")))))) -> 1700～1800 | BS2: =IF(A2="","",IF(AX2="G1","G1",IF(AX2="G2","G2",IF(AX2="G3","G3",IF(AX2="L","L","その他"))))) -> その他 | BT2: =IF(A2="","",IF(BI2="","未結合",IF(D2=BI2,"一致","不一致"))) -> 一致 | BU2: =IF(A2="","",IF(BE2="牝馬限定","牝馬限定","その他")) -> その他
A3: 46228 | B3: 新潟 | C3: 2 | D3: 14 | E3: 4 | F3: ピウモッソ | G3: 37 | H3: 9 | I3: スクワミッシュ | J3: 37 | K3: 1 | L3: エレクトス | M3: 31 | N3: =IF(A3="","",G3-J3) -> 0 | O3: =IF(A3="","",J3-M3) -> 6 | P3: =IF(A3="","",G3+J3) -> 74 | Q3: =IF(A3="","",IF(AND(Y3<>"参考",G3>=ルール設定!$B$2),"○","")) | R3: =IF(A3="","",IF(AND(Y3<>"参考",G3>=ルール設定!$B$3,N3>=ルール設定!$B$4),"○","")) | S3: =IF(A3="","",IF(AND(Y3<>"参考",G3>=ルール設定!$B$5,J3>=ルール設定!$B$6,O3>=ルール設定!$B$7),"○","")) | T3: 4 | U3: 4 | V3: =IF(A3="","",IF(AND(ISNUMBER(T3),ISNUMBER(U3)),IF(AND(T3<=3,U3<=3),"○","×"),"")) -> × | Y3: 事後発見 | Z3: 同率は馬番順で上位3頭欄へ | AI3: 6 | AJ3: ～59 | AK3: 0～4 | AL3: 0～9 | AM3: ～99 | AN3: 12～14 | AO3: =IF(A3="","",IF(COUNTIFS(全馬データ!$A$2:$A$50000,A3,全馬データ!$B$2:$B$50000,B3,全馬データ!$C$2:$C$50000,C3,全馬データ!$D$2:$D$50000,E3,全馬データ!$K$2:$K$50000,"<>")=0,"",SUMIFS(全馬データ!$K$2:$K$50000,全馬データ!$A$2:$A$50000,A3,全馬データ!$B$2:$B$50000,B3,全馬データ!$C$2:$C$50000,C3,全馬データ!$D$2:$D$50000,E3))) | AP3: =IF(A3="","",IF(AO3="","欠損",IF(AO3<=1.1,"1.0～1.1",IF(AO3<1.3,"1.2",IF(AO3<1.5,"1.3～1.4",IF(AO3<2,"1.5～1.9","2.0以上")))))) -> 欠損 | AQ3: =IF(A3="","",IF(ISNUMBER(SEARCH("2歳",Z3)),"2歳戦",IF(ISNUMBER(SEARCH("3歳未勝利",Z3)),"3歳未勝利",IF(ISNUMBER(SEARCH("未勝利",Z3)),"その他未勝利",IF(ISNUMBER(SEARCH("G1",Z3)),"G1",IF(ISNUMBER(SEARCH("G2",Z3)),"G2",IF(ISNUMBER(SEARCH("G3",Z3)),"G3",IF(ISNUMBER(SEARCH("古馬条件",Z3)),"古馬条件戦",IF(ISNUMBER(SEARCH("重賞",Z3)),"重賞","分類不能"))))))))) -> 分類不能 | AS3: 11 | AT3: 2歳 | AU3: A1 | AV3: 新馬 | AY3: 2 | AZ3: ダート | BA3: 1200 | BB3: 20 | BC3: 稍重 | BD3: 102 | BE3: 指定なし | BF3: 0 | BG3: 3 | BH3: 馬齢 | BI3: 14 | BJ3: 2 | BK3: 左 | BL3: 1 | BM3: 通常(内) | BP3: 1 | BQ3: =IF(A3="","",AT3) -> 2歳 | BR3: =IF(A3="","",IF(BA3<=1200,"～1200",IF(BA3<=1500,"1300～1500",IF(BA3=1600,"1600",IF(BA3<=1800,"1700～1800",IF(BA3<=2000,"1900～2000","2100以上")))))) -> ～1200 | BS3: =IF(A3="","",IF(AX3="G1","G1",IF(AX3="G2","G2",IF(AX3="G3","G3",IF(AX3="L","L","その他"))))) -> その他 | BT3: =IF(A3="","",IF(BI3="","未結合",IF(D3=BI3,"一致","不一致"))) -> 一致 | BU3: =IF(A3="","",IF(BE3="牝馬限定","牝馬限定","その他")) -> その他
A4: 46228 | B4: 新潟 | C4: 3 | D4: 8 | E4: 1 | F4: トルタパスカリーナ | G4: 37 | H4: 4 | I4: セプタードアイル | J4: 31 | K4: 3 | L4: スターマイン | M4: 27 | N4: =IF(A4="","",G4-J4) -> 6 | O4: =IF(A4="","",J4-M4) -> 4 | P4: =IF(A4="","",G4+J4) -> 68 | Q4: =IF(A4="","",IF(AND(Y4<>"参考",G4>=ルール設定!$B$2),"○","")) | R4: =IF(A4="","",IF(AND(Y4<>"参考",G4>=ルール設定!$B$3,N4>=ルール設定!$B$4),"○","")) | S4: =IF(A4="","",IF(AND(Y4<>"参考",G4>=ルール設定!$B$5,J4>=ルール設定!$B$6,O4>=ルール設定!$B$7),"○","")) | T4: 2 | U4: 1 | V4: =IF(A4="","",IF(AND(ISNUMBER(T4),ISNUMBER(U4)),IF(AND(T4<=3,U4<=3),"○","×"),"")) -> ○ | W4: 110 | X4: 320 | Y4: 事後発見 | AI4: 10 | AJ4: ～59 | AK4: 5～9 | AL4: 10～19 | AM4: ～99 | AN4: 8～11 | AO4: =IF(A4="","",IF(COUNTIFS(全馬データ!$A$2:$A$50000,A4,全馬データ!$B$2:$B$50000,B4,全馬データ!$C$2:$C$50000,C4,全馬データ!$D$2:$D$50000,E4,全馬データ!$K$2:$K$50000,"<>")=0,"",SUMIFS(全馬データ!$K$2:$K$50000,全馬データ!$A$2:$A$50000,A4,全馬データ!$B$2:$B$50000,B4,全馬データ!$C$2:$C$50000,C4,全馬データ!$D$2:$D$50000,E4))) | AP4: =IF(A4="","",IF(AO4="","欠損",IF(AO4<=1.1,"1.0～1.1",IF(AO4<1.3,"1.2",IF(AO4<1.5,"1.3～1.4",IF(AO4<2,"1.5～1.9","2.0以上")))))) -> 欠損 | AQ4: =IF(A4="","",IF(ISNUMBER(SEARCH("2歳",Z4)),"2歳戦",IF(ISNUMBER(SEARCH("3歳未勝利",Z4)),"3歳未勝利",IF(ISNUMBER(SEARCH("未勝利",Z4)),"その他未勝利",IF(ISNUMBER(SEARCH("G1",Z4)),"G1",IF(ISNUMBER(SEARCH("G2",Z4)),"G2",IF(ISNUMBER(SEARCH("G3",Z4)),"G3",IF(ISNUMBER(SEARCH("古馬条件",Z4)),"古馬条件戦",IF(ISNUMBER(SEARCH("重賞",Z4)),"重賞","分類不能"))))))))) -> 分類不能 | AS4: 11 | AT4: 2歳 | AU4: A1 | AV4: 新馬 | AY4: 1 | AZ4: 芝 | BA4: 1600 | BB4: 11 | BC4: 良 | BD4: 022 | BE4: 牝馬限定 | BF4: 1 | BG4: 3 | BH4: 馬齢 | BI4: 8 | BJ4: 2 | BK4: 左 | BL4: 2 | BM4: 外 | BN4: 1 | BO4: A | BP4: 1 | BQ4: =IF(A4="","",AT4) -> 2歳 | BR4: =IF(A4="","",IF(BA4<=1200,"～1200",IF(BA4<=1500,"1300～1500",IF(BA4=1600,"1600",IF(BA4<=1800,"1700～1800",IF(BA4<=2000,"1900～2000","2100以上")))))) -> 1600 | BS4: =IF(A4="","",IF(AX4="G1","G1",IF(AX4="G2","G2",IF(AX4="G3","G3",IF(AX4="L","L","その他"))))) -> その他 | BT4: =IF(A4="","",IF(BI4="","未結合",IF(D4=BI4,"一致","不一致"))) -> 一致 | BU4: =IF(A4="","",IF(BE4="牝馬限定","牝馬限定","その他")) -> 牝馬限定
A5: 46228 | B5: 新潟 | C5: 4 | D5: 15 | E5: 14 | F5: マナイアカラニ | G5: 58 | H5: 3 | I5: プリプリプリン | J5: 44 | K5: 15 | L5: オレンジキャンパス | M5: 44 | N5: =IF(A5="","",G5-J5) -> 14 | O5: =IF(A5="","",J5-M5) -> 0 | P5: =IF(A5="","",G5+J5) -> 102 | Q5: =IF(A5="","",IF(AND(Y5<>"参考",G5>=ルール設定!$B$2),"○","")) | R5: =IF(A5="","",IF(AND(Y5<>"参考",G5>=ルール設定!$B$3,N5>=ルール設定!$B$4),"○","")) | S5: =IF(A5="","",IF(AND(Y5<>"参考",G5>=ルール設定!$B$5,J5>=ルール設定!$B$6,O5>=ルール設定!$B$7),"○","")) | T5: 4 | U5: 1 | V5: =IF(A5="","",IF(AND(ISNUMBER(T5),ISNUMBER(U5)),IF(AND(T5<=3,U5<=3),"○","×"),"")) -> × | Y5: 事後発見 | Z5: 同率は馬番順で上位3頭欄へ | AI5: 14 | AJ5: ～59 | AK5: 10～19 | AL5: 10～19 | AM5: 100～119 | AN5: 15以上 | AO5: =IF(A5="","",IF(COUNTIFS(全馬データ!$A$2:$A$50000,A5,全馬データ!$B$2:$B$50000,B5,全馬データ!$C$2:$C$50000,C5,全馬データ!$D$2:$D$50000,E5,全馬データ!$K$2:$K$50000,"<>")=0,"",SUMIFS(全馬データ!$K$2:$K$50000,全馬データ!$A$2:$A$50000,A5,全馬データ!$B$2:$B$50000,B5,全馬データ!$C$2:$C$50000,C5,全馬データ!$D$2:$D$50000,E5))) | AP5: =IF(A5="","",IF(AO5="","欠損",IF(AO5<=1.1,"1.0～1.1",IF(AO5<1.3,"1.2",IF(AO5<1.5,"1.3～1.4",IF(AO5<2,"1.5～1.9","2.0以上")))))) -> 欠損 | AQ5: =IF(A5="","",IF(ISNUMBER(SEARCH("2歳",Z5)),"2歳戦",IF(ISNUMBER(SEARCH("3歳未勝利",Z5)),"3歳未勝利",IF(ISNUMBER(SEARCH("未勝利",Z5)),"その他未勝利",IF(ISNUMBER(SEARCH("G1",Z5)),"G1",IF(ISNUMBER(SEARCH("G2",Z5)),"G2",IF(ISNUMBER(SEARCH("G3",Z5)),"G3",IF(ISNUMBER(SEARCH("古馬条件",Z5)),"古馬条件戦",IF(ISNUMBER(SEARCH("重賞",Z5)),"重賞","分類不能"))))))))) -> 分類不能 | AS5: 12 | AT5: 3歳 | AU5: A3 | AV5: 未勝利 | AY5: 2 | AZ5: ダート | BA5: 1200 | BB5: 20 | BC5: 稍重 | BD5: 002 | BE5: 指定なし | BF5: 0 | BG5: 3 | BH5: 馬齢 | BI5: 15 | BJ5: 2 | BK5: 左 | BL5: 1 | BM5: 通常(内) | BP5: 1 | BQ5: =IF(A5="","",AT5) -> 3歳 | BR5: =IF(A5="","",IF(BA5<=1200,"～1200",IF(BA5<=1500,"1300～1500",IF(BA5=1600,"1600",IF(BA5<=1800,"1700～1800",IF(BA5<=2000,"1900～2000","2100以上")))))) -> ～1200 | BS5: =IF(A5="","",IF(AX5="G1","G1",IF(AX5="G2","G2",IF(AX5="G3","G3",IF(AX5="L","L","その他"))))) -> その他 | BT5: =IF(A5="","",IF(BI5="","未結合",IF(D5=BI5,"一致","不一致"))) -> 一致 | BU5: =IF(A5="","",IF(BE5="牝馬限定","牝馬限定","その他")) -> その他
A6: 46228 | B6: 新潟 | C6: 5 | D6: 11 | E6: 5 | F6: フィールドノート | G6: 58 | H6: 7 | I6: オルグジェシダ | J6: 47 | K6: 1 | L6: スワローシチ | M6: 39 | N6: =IF(A6="","",G6-J6) -> 11 | O6: =IF(A6="","",J6-M6) -> 8 | P6: =IF(A6="","",G6+J6) -> 105 | Q6: =IF(A6="","",IF(AND(Y6<>"参考",G6>=ルール設定!$B$2),"○","")) | R6: =IF(A6="","",IF(AND(Y6<>"参考",G6>=ルール設定!$B$3,N6>=ルール設定!$B$4),"○","")) | S6: =IF(A6="","",IF(AND(Y6<>"参考",G6>=ルール設定!$B$5,J6>=ルール設定!$B$6,O6>=ルール設定!$B$7),"○","")) | T6: 1 | U6: 2 | V6: =IF(A6="","",IF(AND(ISNUMBER(T6),ISNUMBER(U6)),IF(AND(T6<=3,U6<=3),"○","×"),"")) -> ○ | W6: 130 | X6: 240 | Y6: 事後発見 | Z6: 同率は馬番順で上位3頭欄へ | AI6: 19 | AJ6: ～59 | AK6: 10～19 | AL6: 10～19 | AM6: 100～119 | AN6: 8～11 | AO6: =IF(A6="","",IF(COUNTIFS(全馬データ!$A$2:$A$50000,A6,全馬データ!$B$2:$B$50000,B6,全馬データ!$C$2:$C$50000,C6,全馬データ!$D$2:$D$50000,E6,全馬データ!$K$2:$K$50000,"<>")=0,"",SUMIFS(全馬データ!$K$2:$K$50000,全馬データ!$A$2:$A$50000,A6,全馬データ!$B$2:$B$50000,B6,全馬データ!$C$2:$C$50000,C6,全馬データ!$D$2:$D$50000,E6))) | AP6: =IF(A6="","",IF(AO6="","欠損",IF(AO6<=1.1,"1.0～1.1",IF(AO6<1.3,"1.2",IF(AO6<1.5,"1.3～1.4",IF(AO6<2,"1.5～1.9","2.0以上")))))) -> 欠損 | AQ6: =IF(A6="","",IF(ISNUMBER(SEARCH("2歳",Z6)),"2歳戦",IF(ISNUMBER(SEARCH("3歳未勝利",Z6)),"3歳未勝利",IF(ISNUMBER(SEARCH("未勝利",Z6)),"その他未勝利",IF(ISNUMBER(SEARCH("G1",Z6)),"G1",IF(ISNUMBER(SEARCH("G2",Z6)),"G2",IF(ISNUMBER(SEARCH("G3",Z6)),"G3",IF(ISNUMBER(SEARCH("古馬条件",Z6)),"古馬条件戦",IF(ISNUMBER(SEARCH("重賞",Z6)),"重賞","分類不能"))))))))) -> 分類不能 | AS6: 13 | AT6: 3歳以上 | AU6: 05 | AV6: 1勝クラス | AY6: 1 | AZ6: 芝 | BA6: 1800 | BB6: 11 | BC6: 良 | BD6: 103 | BE6: 指定なし | BF6: 0 | BG6: 4 | BH6: 定量 | BI6: 11 | BJ6: 2 | BK6: 左 | BL6: 2 | BM6: 外 | BN6: 1 | BO6: A | BP6: 1 | BQ6: =IF(A6="","",AT6) -> 3歳以上 | BR6: =IF(A6="","",IF(BA6<=1200,"～1200",IF(BA6<=1500,"1300～1500",IF(BA6=1600,"1600",IF(BA6<=1800,"1700～1800",IF(BA6<=2000,"1900～2000","2100以上")))))) -> 1700～1800 | BS6: =IF(A6="","",IF(AX6="G1","G1",IF(AX6="G2","G2",IF(AX6="G3","G3",IF(AX6="L","L","その他"))))) -> その他 | BT6: =IF(A6="","",IF(BI6="","未結合",IF(D6=BI6,"一致","不一致"))) -> 一致 | BU6: =IF(A6="","",IF(BE6="牝馬限定","牝馬限定","その他")) -> その他
A7: 46228 | B7: 新潟 | C7: 6 | D7: 15 | E7: 14 | F7: シャンソンドール | G7: 62 | H7: 9 | I7: ジーネキング | J7: 50 | K7: 3 | L7: ラビットアイ | M7: 44 | N7: =IF(A7="","",G7-J7) -> 12 | O7: =IF(A7="","",J7-M7) -> 6 | P7: =IF(A7="","",G7+J7) -> 112 | Q7: =IF(A7="","",IF(AND(Y7<>"参考",G7>=ルール設定!$B$2),"○","")) | R7: =IF(A7="","",IF(AND(Y7<>"参考",G7>=ルール設定!$B$3,N7>=ルール設定!$B$4),"○","")) | S7: =IF(A7="","",IF(AND(Y7<>"参考",G7>=ルール設定!$B$5,J7>=ルール設定!$B$6,O7>=ルール設定!$B$7),"○","")) | T7: 3 | U7: 2 | V7: =IF(A7="","",IF(AND(ISNUMBER(T7),ISNUMBER(U7)),IF(AND(T7<=3,U7<=3),"○","×"),"")) -> ○ | W7: 130 | X7: 330 | Y7: 事後発見 | AI7: 18 | AJ7: 60～69 | AK7: 10～19 | AL7: 10～19 | AM7: 100～119 | AN7: 15以上 | AO7: =IF(A7="","",IF(COUNTIFS(全馬データ!$A$2:$A$50000,A7,全馬データ!$B$2:$B$50000,B7,全馬データ!$C$2:$C$50000,C7,全馬データ!$D$2:$D$50000,E7,全馬データ!$K$2:$K$50000,"<>")=0,"",SUMIFS(全馬データ!$K$2:$K$50000,全馬データ!$A$2:$A$50000,A7,全馬データ!$B$2:$B$50000,B7,全馬データ!$C$2:$C$50000,C7,全馬データ!$D$2:$D$50000,E7))) | AP7: =IF(A7="","",IF(AO7="","欠損",IF(AO7<=1.1,"1.0～1.1",IF(AO7<1.3,"1.2",IF(AO7<1.5,"1.3～1.4",IF(AO7<2,"1.5～1.9","2.0以上")))))) -> 欠損 | AQ7: =IF(A7="","",IF(ISNUMBER(SEARCH("2歳",Z7)),"2歳戦",IF(ISNUMBER(SEARCH("3歳未勝利",Z7)),"3歳未勝利",IF(ISNUMBER(SEARCH("未勝利",Z7)),"その他未勝利",IF(ISNUMBER(SEARCH("G1",Z7)),"G1",IF(ISNUMBER(SEARCH("G2",Z7)),"G2",IF(ISNUMBER(SEARCH("G3",Z7)),"G3",IF(ISNUMBER(SEARCH("古馬条件",Z7)),"古馬条件戦",IF(ISNUMBER(SEARCH("重賞",Z7)),"重賞","分類不能"))))))))) -> 分類不能 | AR7: 豊栄特別 | AS7: 13 | AT7: 3歳以上 | AU7: 10 | AV7: 2勝クラス | AW7: 5 | AX7: 特別 | AY7: 1 | AZ7: 芝 | BA7: 1600 | BB7: 11 | BC7: 良 | BD7: 103 | BE7: 指定なし | BF7: 0 | BG7: 4 | BH7: 定量 | BI7: 15 | BJ7: 2 | BK7: 左 | BL7: 2 | BM7: 外 | BN7: 1 | BO7: A | BP7: 1 | BQ7: =IF(A7="","",AT7) -> 3歳以上 | BR7: =IF(A7="","",IF(BA7<=1200,"～1200",IF(BA7<=1500,"1300～1500",IF(BA7=1600,"1600",IF(BA7<=1800,"1700～1800",IF(BA7<=2000,"1900～2000","2100以上")))))) -> 1600 | BS7: =IF(A7="","",IF(AX7="G1","G1",IF(AX7="G2","G2",IF(AX7="G3","G3",IF(AX7="L","L","その他"))))) -> その他 | BT7: =IF(A7="","",IF(BI7="","未結合",IF(D7=BI7,"一致","不一致"))) -> 一致 | BU7: =IF(A7="","",IF(BE7="牝馬限定","牝馬限定","その他")) -> その他
A8: 46228 | B8: 新潟 | C8: 7 | D8: 18 | E8: 2 | F8: コートアリシアン | G8: 67 | H8: 17 | I8: モジャーリオミ | J8: 31 | K8: 8 | L8: ポボンヌソワレ | M8: 29 | N8: =IF(A8="","",G8-J8) -> 36 | O8: =IF(A8="","",J8-M8) -> 2 | P8: =IF(A8="","",G8+J8) -> 98 | Q8: =IF(A8="","",IF(AND(Y8<>"参考",G8>=ルール設定!$B$2),"○","")) | R8: =IF(A8="","",IF(AND(Y8<>"参考",G8>=ルール設定!$B$3,N8>=ルール設定!$B$4),"○","")) | S8: =IF(A8="","",IF(AND(Y8<>"参考",G8>=ルール設定!$B$5,J8>=ルール設定!$B$6,O8>=ルール設定!$B$7),"○","")) | T8: 4 | U8: 4 | V8: =IF(A8="","",IF(AND(ISNUMBER(T8),ISNUMBER(U8)),IF(AND(T8<=3,U8<=3),"○","×"),"")) -> × | Y8: 事後発見 | AI8: 38 | AJ8: 60～69 | AK8: 30以上 | AL8: 30～39 | AM8: ～99 | AN8: 15以上 | AO8: =IF(A8="","",IF(COUNTIFS(全馬データ!$A$2:$A$50000,A8,全馬データ!$B$2:$B$50000,B8,全馬データ!$C$2:$C$50000,C8,全馬データ!$D$2:$D$50000,E8,全馬データ!$K$2:$K$50000,"<>")=0,"",SUMIFS(全馬データ!$K$2:$K$50000,全馬データ!$A$2:$A$50000,A8,全馬データ!$B$2:$B$50000,B8,全馬データ!$C$2:$C$50000,C8,全馬データ!$D$2:$D$50000,E8))) | AP8: =IF(A8="","",IF(AO8="","欠損",IF(AO8<=1.1,"1.0～1.1",IF(AO8<1.3,"1.2",IF(AO8<1.5,"1.3～1.4",IF(AO8<2,"1.5～1.9","2.0以上")))))) -> 欠損 | AQ8: =IF(A8="","",IF(ISNUMBER(SEARCH("2歳",Z8)),"2歳戦",IF(ISNUMBER(SEARCH("3歳未勝利",Z8)),"3歳未勝利",IF(ISNUMBER(SEARCH("未勝利",Z8)),"その他未勝利",IF(ISNUMBER(SEARCH("G1",Z8)),"G1",IF(ISNUMBER(SEARCH("G2",Z8)),"G2",IF(ISNUMBER(SEARCH("G3",Z8)),"G3",IF(ISNUMBER(SEARCH("古馬条件",Z8)),"古馬条件戦",IF(ISNUMBER(SEARCH("重賞",Z8)),"重賞","分類不能"))))))))) -> 分類不能 | AR8: 新潟日報賞 | AS8: 13 | AT8: 3歳以上 | AU8: 16 | AV8: 3勝クラス | AW8: 5 | AX8: 特別 | AY8: 1 | AZ8: 芝 | BA8: 1400 | BB8: 11 | BC8: 良 | BD8: 103 | BE8: 指定なし | BF8: 0 | BG8: 4 | BH8: 定量 | BI8: 18 | BJ8: 2 | BK8: 左 | BL8: 1 | BM8: 通常(内) | BN8: 1 | BO8: A | BP8: 1 | BQ8: =IF(A8="","",AT8) -> 3歳以上 | BR8: =IF(A8="","",IF(BA8<=1200,"～1200",IF(BA8<=1500,"1300～1500",IF(BA8=1600,"1600",IF(BA8<=1800,"1700～1800",IF(BA8<=2000,"1900～2000","2100以上")))))) -> 1300～1500 | BS8: =IF(A8="","",IF(AX8="G1","G1",IF(AX8="G2","G2",IF(AX8="G3","G3",IF(AX8="L","L","その他"))))) -> その他 | BT8: =IF(A8="","",IF(BI8="","未結合",IF(D8=BI8,"一致","不一致"))) -> 一致 | BU8: =IF(A8="","",IF(BE8="牝馬限定","牝馬限定","その他")) -> その他
A9: 46228 | B9: 新潟 | C9: 8 | D9: 13 | E9: 10 | F9: パイオニアスクエア | G9: 62 | H9: 11 | I9: インナーバパッション | J9: 60 | K9: 5 | L9: イリュストル | M9: 37 | N9: =IF(A9="","",G9-J9) -> 2 | O9: =IF(A9="","",J9-M9) -> 23 | P9: =IF(A9="","",G9+J9) -> 122 | Q9: =IF(A9="","",IF(AND(Y9<>"参考",G9>=ルール設定!$B$2),"○","")) | R9: =IF(A9="","",IF(AND(Y9<>"参考",G9>=ルール設定!$B$3,N9>=ルール設定!$B$4),"○","")) | S9: =IF(A9="","",IF(AND(Y9<>"参考",G9>=ルール設定!$B$5,J9>=ルール設定!$B$6,O9>=ルール設定!$B$7),"○","")) -> ○ | T9: 2 | U9: 4 | V9: =IF(A9="","",IF(AND(ISNUMBER(T9),ISNUMBER(U9)),IF(AND(T9<=3,U9<=3),"○","×"),"")) -> × | W9: 200 | Y9: 事後発見 | AI9: 25 | AJ9: 60～69 | AK9: 0～4 | AL9: 20～29 | AM9: 120～139 | AN9: 12～14 | AO9: =IF(A9="","",IF(COUNTIFS(全馬データ!$A$2:$A$50000,A9,全馬データ!$B$2:$B$50000,B9,全馬データ!$C$2:$C$50000,C9,全馬データ!$D$2:$D$50000,E9,全馬データ!$K$2:$K$50000,"<>")=0,"",SUMIFS(全馬データ!$K$2:$K$50000,全馬データ!$A$2:$A$50000,A9,全馬データ!$B$2:$B$50000,B9,全馬データ!$C$2:$C$50000,C9,全馬データ!$D$2:$D$50000,E9))) | AP9: =IF(A9="","",IF(AO9="","欠損",IF(AO9<=1.1,"1.0～1.1",IF(AO9<1.3,"1.2",IF(AO9<1.5,"1.3～1.4",IF(AO9<2,"1.5～1.9","2.0以上")))))) -> 欠損 | AQ9: =IF(A9="","",IF(ISNUMBER(SEARCH("2歳",Z9)),"2歳戦",IF(ISNUMBER(SEARCH("3歳未勝利",Z9)),"3歳未勝利",IF(ISNUMBER(SEARCH("未勝利",Z9)),"その他未勝利",IF(ISNUMBER(SEARCH("G1",Z9)),"G1",IF(ISNUMBER(SEARCH("G2",Z9)),"G2",IF(ISNUMBER(SEARCH("G3",Z9)),"G3",IF(ISNUMBER(SEARCH("古馬条件",Z9)),"古馬条件戦",IF(ISNUMBER(SEARCH("重賞",Z9)),"重賞","分類不能"))))))))) -> 分類不能 | AR9: 清津峡特別 | AS9: 13 | AT9: 3歳以上 | AU9: 05 | AV9: 1勝クラス | AW9: 5 | AX9: 特別 | AY9: 2 | AZ9: ダート | BA9: 1800 | BB9: 20 | BC9: 稍重 | BD9: 102 | BE9: 指定なし | BF9: 0 | BG9: 4 | BH9: 定量 | BI9: 13 | BJ9: 2 | BK9: 左 | BL9: 1 | BM9: 通常(内) | BP9: 1 | BQ9: =IF(A9="","",AT9) -> 3歳以上 | BR9: =IF(A9="","",IF(BA9<=1200,"～1200",IF(BA9<=1500,"1300～1500",IF(BA9=1600,"1600",IF(BA9<=1800,"1700～1800",IF(BA9<=2000,"1900～2000","2100以上")))))) -> 1700～1800 | BS9: =IF(A9="","",IF(AX9="G1","G1",IF(AX9="G2","G2",IF(AX9="G3","G3",IF(AX9="L","L","その他"))))) -> その他 | BT9: =IF(A9="","",IF(BI9="","未結合",IF(D9=BI9,"一致","不一致"))) -> 一致 | BU9: =IF(A9="","",IF(BE9="牝馬限定","牝馬限定","その他")) -> その他
A10: 46228 | B10: 新潟 | C10: 9 | D10: 10 | E10: 3 | F10: スコラーリmm | G10: 55 | H10: 8 | I10: モンツァフレイバー | J10: 44 | K10: 1 | L10: ウォータダターリーダー | M10: 37 | N10: =IF(A10="","",G10-J10) -> 11 | O10: =IF(A10="","",J10-M10) -> 7 | P10: =IF(A10="","",G10+J10) -> 99 | Q10: =IF(A10="","",IF(AND(Y10<>"参考",G10>=ルール設定!$B$2),"○","")) | R10: =IF(A10="","",IF(AND(Y10<>"参考",G10>=ルール設定!$B$3,N10>=ルール設定!$B$4),"○","")) | S10: =IF(A10="","",IF(AND(Y10<>"参考",G10>=ルール設定!$B$5,J10>=ルール設定!$B$6,O10>=ルール設定!$B$7),"○","")) | T10: 4 | U10: 1 | V10: =IF(A10="","",IF(AND(ISNUMBER(T10),ISNUMBER(U10)),IF(AND(T10<=3,U10<=3),"○","×"),"")) -> × | Y10: 事後発見 | Z10: 同率は馬番順で上位3頭欄へ | AI10: 18 | AJ10: ～59 | AK10: 10～19 | AL10: 10～19 | AM10: ～99 | AN10: 8～11 | AO10: =IF(A10="","",IF(COUNTIFS(全馬データ!$A$2:$A$50000,A10,全馬データ!$B$2:$B$50000,B10,全馬データ!$C$2:$C$50000,C10,全馬データ!$D$2:$D$50000,E10,全馬データ!$K$2:$K$50000,"<>")=0,"",SUMIFS(全馬データ!$K$2:$K$50000,全馬データ!$A$2:$A$50000,A10,全馬データ!$B$2:$B$50000,B10,全馬データ!$C$2:$C$50000,C10,全馬データ!$D$2:$D$50000,E10))) | AP10: =IF(A10="","",IF(AO10="","欠損",IF(AO10<=1.1,"1.0～1.1",IF(AO10<1.3,"1.2",IF(AO10<1.5,"1.3～1.4",IF(AO10<2,"1.5～1.9","2.0以上")))))) -> 欠損 | AQ10: =IF(A10="","",IF(ISNUMBER(SEARCH("2歳",Z10)),"2歳戦",IF(ISNUMBER(SEARCH("3歳未勝利",Z10)),"3歳未勝利",IF(ISNUMBER(SEARCH("未勝利",Z10)),"その他未勝利",IF(ISNUMBER(SEARCH("G1",Z10)),"G1",IF(ISNUMBER(SEARCH("G2",Z10)),"G2",IF(ISNUMBER(SEARCH("G3",Z10)),"G3",IF(ISNUMBER(SEARCH("古馬条件",Z10)),"古馬条件戦",IF(ISNUMBER(SEARCH("重賞",Z10)),"重賞","分類不能"))))))))) -> 分類不能 | AS10: 20 | AT10: 障害 | AU10: OP | AV10: オープン | AY10: 3 | AZ10: 障害 | BA10: 2850 | BB10: 10 | BC10: 良 | BD10: 100 | BE10: 指定なし | BF10: 0 | BG10: 2 | BH10: 別定 | BI10: 10 | BJ10: 9 | BK10: 他 | BL10: 9 | BM10: 他 | BP10: 1 | BQ10: =IF(A10="","",AT10) -> 障害 | BR10: =IF(A10="","",IF(BA10<=1200,"～1200",IF(BA10<=1500,"1300～1500",IF(BA10=1600,"1600",IF(BA10<=1800,"1700～1800",IF(BA10<=2000,"1900～2000","2100以上")))))) -> 2100以上 | BS10: =IF(A10="","",IF(AX10="G1","G1",IF(AX10="G2","G2",IF(AX10="G3","G3",IF(AX10="L","L","その他"))))) -> その他 | BT10: =IF(A10="","",IF(BI10="","未結合",IF(D10=BI10,"一致","不一致"))) -> 一致 | BU10: =IF(A10="","",IF(BE10="牝馬限定","牝馬限定","その他")) -> その他
A11: 46228 | B11: 新潟 | C11: 10 | D11: 15 | E11: 1 | F11: シェリーシュシュ | G11: 62 | H11: 12 | I11: カーボフリオ | J11: 52 | K11: 9 | L11: ゴールドビリーヴ | M11: 47 | N11: =IF(A11="","",G11-J11) -> 10 | O11: =IF(A11="","",J11-M11) -> 5 | P11: =IF(A11="","",G11+J11) -> 114 | Q11: =IF(A11="","",IF(AND(Y11<>"参考",G11>=ルール設定!$B$2),"○","")) | R11: =IF(A11="","",IF(AND(Y11<>"参考",G11>=ルール設定!$B$3,N11>=ルール設定!$B$4),"○","")) | S11: =IF(A11="","",IF(AND(Y11<>"参考",G11>=ルール設定!$B$5,J11>=ルール設定!$B$6,O11>=ルール設定!$B$7),"○","")) | T11: 4 | U11: 3 | V11: =IF(A11="","",IF(AND(ISNUMBER(T11),ISNUMBER(U11)),IF(AND(T11<=3,U11<=3),"○","×"),"")) -> × | Y11: 事後発見 | AI11: 15 | AJ11: 60～69 | AK11: 10～19 | AL11: 10～19 | AM11: 100～119 | AN11: 15以上 | AO11: =IF(A11="","",IF(COUNTIFS(全馬データ!$A$2:$A$50000,A11,全馬データ!$B$2:$B$50000,B11,全馬データ!$C$2:$C$50000,C11,全馬データ!$D$2:$D$50000,E11,全馬データ!$K$2:$K$50000,"<>")=0,"",SUMIFS(全馬データ!$K$2:$K$50000,全馬データ!$A$2:$A$50000,A11,全馬データ!$B$2:$B$50000,B11,全馬データ!$C$2:$C$50000,C11,全馬データ!$D$2:$D$50000,E11))) | AP11: =IF(A11="","",IF(AO11="","欠損",IF(AO11<=1.1,"1.0～1.1",IF(AO11<1.3,"1.2",IF(AO11<1.5,"1.3～1.4",IF(AO11<2,"1.5～1.9","2.0以上")))))) -> 欠損 | AQ11: =IF(A11="","",IF(ISNUMBER(SEARCH("2歳",Z11)),"2歳戦",IF(ISNUMBER(SEARCH("3歳未勝利",Z11)),"3歳未勝利",IF(ISNUMBER(SEARCH("未勝利",Z11)),"その他未勝利",IF(ISNUMBER(SEARCH("G1",Z11)),"G1",IF(ISNUMBER(SEARCH("G2",Z11)),"G2",IF(ISNUMBER(SEARCH("G3",Z11)),"G3",IF(ISNUMBER(SEARCH("古馬条件",Z11)),"古馬条件戦",IF(ISNUMBER(SEARCH("重賞",Z11)),"重賞","分類不能"))))))))) -> 分類不能 | AS11: 12 | AT11: 3歳 | AU11: A3 | AV11: 未勝利 | AY11: 2 | AZ11: ダート | BA11: 1800 | BB11: 20 | BC11: 稍重 | BD11: 022 | BE11: 牝馬限定 | BF11: 1 | BG11: 3 | BH11: 馬齢 | BI11: 15 | BJ11: 2 | BK11: 左 | BL11: 1 | BM11: 通常(内) | BP11: 1 | BQ11: =IF(A11="","",AT11) -> 3歳 | BR11: =IF(A11="","",IF(BA11<=1200,"～1200",IF(BA11<=1500,"1300～1500",IF(BA11=1600,"1600",IF(BA11<=1800,"1700～1800",IF(BA11<=2000,"1900～2000","2100以上")))))) -> 1700～1800 | BS11: =IF(A11="","",IF(AX11="G1","G1",IF(AX11="G2","G2",IF(AX11="G3","G3",IF(AX11="L","L","その他"))))) -> その他 | BT11: =IF(A11="","",IF(BI11="","未結合",IF(D11=BI11,"一致","不一致"))) -> 一致 | BU11: =IF(A11="","",IF(BE11="牝馬限定","牝馬限定","その他")) -> 牝馬限定
A12: 46228 | B12: 新潟 | C12: 11 | D12: 18 | E12: 16 | F12: シルバーアックス | G12: 67 | H12: 18 | I12: ジョイアミーアミ | J12: 56 | K12: 4 | L12: リオクリスハーレー | M12: 31 | N12: =IF(A12="","",G12-J12) -> 11 | O12: =IF(A12="","",J12-M12) -> 25 | P12: =IF(A12="","",G12+J12) -> 123 | Q12: =IF(A12="","",IF(AND(Y12<>"参考",G12>=ルール設定!$B$2),"○","")) | R12: =IF(A12="","",IF(AND(Y12<>"参考",G12>=ルール設定!$B$3,N12>=ルール設定!$B$4),"○","")) | S12: =IF(A12="","",IF(AND(Y12<>"参考",G12>=ルール設定!$B$5,J12>=ルール設定!$B$6,O12>=ルール設定!$B$7),"○","")) -> ○ | T12: 4 | U12: 4 | V12: =IF(A12="","",IF(AND(ISNUMBER(T12),ISNUMBER(U12)),IF(AND(T12<=3,U12<=3),"○","×"),"")) -> × | Y12: 事後発見 | AI12: 36 | AJ12: 60～69 | AK12: 10～19 | AL12: 30～39 | AM12: 120～139 | AN12: 15以上 | AO12: =IF(A12="","",IF(COUNTIFS(全馬データ!$A$2:$A$50000,A12,全馬データ!$B$2:$B$50000,B12,全馬データ!$C$2:$C$50000,C12,全馬データ!$D$2:$D$50000,E12,全馬データ!$K$2:$K$50000,"<>")=0,"",SUMIFS(全馬データ!$K$2:$K$50000,全馬データ!$A$2:$A$50000,A12,全馬データ!$B$2:$B$50000,B12,全馬データ!$C$2:$C$50000,C12,全馬データ!$D$2:$D$50000,E12))) | AP12: =IF(A12="","",IF(AO12="","欠損",IF(AO12<=1.1,"1.0～1.1",IF(AO12<1.3,"1.2",IF(AO12<1.5,"1.3～1.4",IF(AO12<2,"1.5～1.9","2.0以上")))))) -> 欠損 | AQ12: =IF(A12="","",IF(ISNUMBER(SEARCH("2歳",Z12)),"2歳戦",IF(ISNUMBER(SEARCH("3歳未勝利",Z12)),"3歳未勝利",IF(ISNUMBER(SEARCH("未勝利",Z12)),"その他未勝利",IF(ISNUMBER(SEARCH("G1",Z12)),"G1",IF(ISNUMBER(SEARCH("G2",Z12)),"G2",IF(ISNUMBER(SEARCH("G3",Z12)),"G3",IF(ISNUMBER(SEARCH("古馬条件",Z12)),"古馬条件戦",IF(ISNUMBER(SEARCH("重賞",Z12)),"重賞","分類不能"))))))))) -> 分類不能 | AS12: 12 | AT12: 3歳 | AU12: A3 | AV12: 未勝利 | AY12: 1 | AZ12: 芝 | BA12: 1000 | BB12: 11 | BC12: 良 | BD12: 002 | BE12: 指定なし | BF12: 0 | BG12: 3 | BH12: 馬齢 | BI12: 18 | BJ12: 3 | BK12: 直 | BL12: 9 | BM12: 他 | BN12: 1 | BO12: A | BP12: 1 | BQ12: =IF(A12="","",AT12) -> 3歳 | BR12: =IF(A12="","",IF(BA12<=1200,"～1200",IF(BA12<=1500,"1300～1500",IF(BA12=1600,"1600",IF(BA12<=1800,"1700～1800",IF(BA12<=2000,"1900～2000","2100以上")))))) -> ～1200 | BS12: =IF(A12="","",IF(AX12="G1","G1",IF(AX12="G2","G2",IF(AX12="G3","G3",IF(AX12="L","L","その他"))))) -> その他 | BT12: =IF(A12="","",IF(BI12="","未結合",IF(D12=BI12,"一致","不一致"))) -> 一致 | BU12: =IF(A12="","",IF(BE12="牝馬限定","牝馬限定","その他")) -> その他
A13: 46228 | B13: 新潟 | C13: 12 | D13: 17 | E13: 15 | F13: タイセイフレッサ | G13: 67 | H13: 4 | I13: ルージュダリア | J13: 39 | K13: 11 | L13: ガラク | M13: 37 | N13: =IF(A13="","",G13-J13) -> 28 | O13: =IF(A13="","",J13-M13) -> 2 | P13: =IF(A13="","",G13+J13) -> 106 | Q13: =IF(A13="","",IF(AND(Y13<>"参考",G13>=ルール設定!$B$2),"○","")) | R13: =IF(A13="","",IF(AND(Y13<>"参考",G13>=ルール設定!$B$3,N13>=ルール設定!$B$4),"○","")) | S13: =IF(A13="","",IF(AND(Y13<>"参考",G13>=ルール設定!$B$5,J13>=ルール設定!$B$6,O13>=ルール設定!$B$7),"○","")) | T13: 4 | U13: 4 | V13: =IF(A13="","",IF(AND(ISNUMBER(T13),ISNUMBER(U13)),IF(AND(T13<=3,U13<=3),"○","×"),"")) -> × | Y13: 事後発見 | AI13: 30 | AJ13: 60～69 | AK13: 20～29 | AL13: 30～39 | AM13: 100～119 | AN13: 15以上 | AO13: =IF(A13="","",IF(COUNTIFS(全馬データ!$A$2:$A$50000,A13,全馬データ!$B$2:$B$50000,B13,全馬データ!$C$2:$C$50000,C13,全馬データ!$D$2:$D$50000,E13,全馬データ!$K$2:$K$50000,"<>")=0,"",SUMIFS(全馬データ!$K$2:$K$50000,全馬データ!$A$2:$A$50000,A13,全馬データ!$B$2:$B$50000,B13,全馬データ!$C$2:$C$50000,C13,全馬データ!$D$2:$D$50000,E13))) | AP13: =IF(A13="","",IF(AO13="","欠損",IF(AO13<=1.1,"1.0～1.1",IF(AO13<1.3,"1.2",IF(AO13<1.5,"1.3～1.4",IF(AO13<2,"1.5～1.9","2.0以上")))))) -> 欠損 | AQ13: =IF(A13="","",IF(ISNUMBER(SEARCH("2歳",Z13)),"2歳戦",IF(ISNUMBER(SEARCH("3歳未勝利",Z13)),"3歳未勝利",IF(ISNUMBER(SEARCH("未勝利",Z13)),"その他未勝利",IF(ISNUMBER(SEARCH("G1",Z13)),"G1",IF(ISNUMBER(SEARCH("G2",Z13)),"G2",IF(ISNUMBER(SEARCH("G3",Z13)),"G3",IF(ISNUMBER(SEARCH("古馬条件",Z13)),"古馬条件戦",IF(ISNUMBER(SEARCH("重賞",Z13)),"重賞","分類不能"))))))))) -> 分類不能 | AS13: 13 | AT13: 3歳以上 | AU13: 05 | AV13: 1勝クラス | AY13: 1 | AZ13: 芝 | BA13: 1400 | BB13: 11 | BC13: 良 | BD13: 022 | BE13: 牝馬限定 | BF13: 1 | BG13: 4 | BH13: 定量 | BI13: 17 | BJ13: 2 | BK13: 左 | BL13: 1 | BM13: 通常(内) | BN13: 1 | BO13: A | BP13: 1 | BQ13: =IF(A13="","",AT13) -> 3歳以上 | BR13: =IF(A13="","",IF(BA13<=1200,"～1200",IF(BA13<=1500,"1300～1500",IF(BA13=1600,"1600",IF(BA13<=1800,"1700～1800",IF(BA13<=2000,"1900～2000","2100以上")))))) -> 1300～1500 | BS13: =IF(A13="","",IF(AX13="G1","G1",IF(AX13="G2","G2",IF(AX13="G3","G3",IF(AX13="L","L","その他"))))) -> その他 | BT13: =IF(A13="","",IF(BI13="","未結合",IF(D13=BI13,"一致","不一致"))) -> 一致 | BU13: =IF(A13="","",IF(BE13="牝馬限定","牝馬限定","その他")) -> 牝馬限定
A14: 46228 | B14: 中京 | C14: 1 | D14: 9 | E14: 5 | F14: エルダークローネ | G14: 81 | H14: 1 | I14: レッドネビュラ | J14: 37 | K14: 6 | L14: エコロメジャー | M14: 34 | N14: =IF(A14="","",G14-J14) -> 44 | O14: =IF(A14="","",J14-M14) -> 3 | P14: =IF(A14="","",G14+J14) -> 118 | Q14: =IF(A14="","",IF(AND(Y14<>"参考",G14>=ルール設定!$B$2),"○","")) -> ○ | R14: =IF(A14="","",IF(AND(Y14<>"参考",G14>=ルール設定!$B$3,N14>=ルール設定!$B$4),"○","")) -> ○ | S14: =IF(A14="","",IF(AND(Y14<>"参考",G14>=ルール設定!$B$5,J14>=ルール設定!$B$6,O14>=ルール設定!$B$7),"○","")) | T14: 4 | U14: 1 | V14: =IF(A14="","",IF(AND(ISNUMBER(T14),ISNUMBER(U14)),IF(AND(T14<=3,U14<=3),"○","×"),"")) -> × | Y14: 事後発見 | AB14: ○ | AD14: ○ | AG14: ○ | AI14: 47 | AJ14: 80～84 | AK14: 30以上 | AL14: 40以上 | AM14: 100～119 | AN14: 8～11 | AO14: =IF(A14="","",IF(COUNTIFS(全馬データ!$A$2:$A$50000,A14,全馬データ!$B$2:$B$50000,B14,全馬データ!$C$2:$C$50000,C14,全馬データ!$D$2:$D$50000,E14,全馬データ!$K$2:$K$50000,"<>")=0,"",SUMIFS(全馬データ!$K$2:$K$50000,全馬データ!$A$2:$A$50000,A14,全馬データ!$B$2:$B$50000,B14,全馬データ!$C$2:$C$50000,C14,全馬データ!$D$2:$D$50000,E14))) -> 1.1 | AP14: =IF(A14="","",IF(AO14="","欠損",IF(AO14<=1.1,"1.0～1.1",IF(AO14<1.3,"1.2",IF(AO14<1.5,"1.3～1.4",IF(AO14<2,"1.5～1.9","2.0以上")))))) -> 1.0～1.1 | AQ14: =IF(A14="","",IF(ISNUMBER(SEARCH("2歳",Z14)),"2歳戦",IF(ISNUMBER(SEARCH("3歳未勝利",Z14)),"3歳未勝利",IF(ISNUMBER(SEARCH("未勝利",Z14)),"その他未勝利",IF(ISNUMBER(SEARCH("G1",Z14)),"G1",IF(ISNUMBER(SEARCH("G2",Z14)),"G2",IF(ISNUMBER(SEARCH("G3",Z14)),"G3",IF(ISNUMBER(SEARCH("古馬条件",Z14)),"古馬条件戦",IF(ISNUMBER(SEARCH("重賞",Z14)),"重賞","分類不能"))))))))) -> 分類不能 | AS14: 11 | AT14: 2歳 | AU14: A3 | AV14: 未勝利 | AY14: 2 | AZ14: ダート | BA14: 1200 | BB14: 10 | BC14: 良 | BD14: 102 | BE14: 指定なし | BF14: 0 | BG14: 3 | BH14: 馬齢 | BI14: 9 | BJ14: 2 | BK14: 左 | BL14: 1 | BM14: 通常(内) | BP14: 2 | BQ14: =IF(A14="","",AT14) -> 2歳 | BR14: =IF(A14="","",IF(BA14<=1200,"～1200",IF(BA14<=1500,"1300～1500",IF(BA14=1600,"1600",IF(BA14<=1800,"1700～1800",IF(BA14<=2000,"1900～2000","2100以上")))))) -> ～1200 | BS14: =IF(A14="","",IF(AX14="G1","G1",IF(AX14="G2","G2",IF(AX14="G3","G3",IF(AX14="L","L","その他"))))) -> その他 | BT14: =IF(A14="","",IF(BI14="","未結合",IF(D14=BI14,"一致","不一致"))) -> 一致 | BU14: =IF(A14="","",IF(BE14="牝馬限定","牝馬限定","その他")) -> その他
A15: 46228 | B15: 中京 | C15: 2 | D15: 13 | E15: 11 | F15: ブレイクアウェイ | G15: 31 | H15: 5 | I15: テーオーライガ | J15: 24 | K15: 13 | L15: ベルヴェール | M15: 24 | N15: =IF(A15="","",G15-J15) -> 7 | O15: =IF(A15="","",J15-M15) -> 0 | P15: =IF(A15="","",G15+J15) -> 55 | Q15: =IF(A15="","",IF(AND(Y15<>"参考",G15>=ルール設定!$B$2),"○","")) | R15: =IF(A15="","",IF(AND(Y15<>"参考",G15>=ルール設定!$B$3,N15>=ルール設定!$B$4),"○","")) | S15: =IF(A15="","",IF(AND(Y15<>"参考",G15>=ルール設定!$B$5,J15>=ルール設定!$B$6,O15>=ルール設定!$B$7),"○","")) | T15: 1 | U15: 4 | V15: =IF(A15="","",IF(AND(ISNUMBER(T15),ISNUMBER(U15)),IF(AND(T15<=3,U15<=3),"○","×"),"")) -> × | W15: 110 | Y15: 事後発見 | Z15: 同率は馬番順で上位3頭欄へ | AI15: 7 | AJ15: ～59 | AK15: 5～9 | AL15: 0～9 | AM15: ～99 | AN15: 12～14 | AO15: =IF(A15="","",IF(COUNTIFS(全馬データ!$A$2:$A$50000,A15,全馬データ!$B$2:$B$50000,B15,全馬データ!$C$2:$C$50000,C15,全馬データ!$D$2:$D$50000,E15,全馬データ!$K$2:$K$50000,"<>")=0,"",SUMIFS(全馬データ!$K$2:$K$50000,全馬データ!$A$2:$A$50000,A15,全馬データ!$B$2:$B$50000,B15,全馬データ!$C$2:$C$50000,C15,全馬データ!$D$2:$D$50000,E15))) | AP15: =IF(A15="","",IF(AO15="","欠損",IF(AO15<=1.1,"1.0～1.1",IF(AO15<1.3,"1.2",IF(AO15<1.5,"1.3～1.4",IF(AO15<2,"1.5～1.9","2.0以上")))))) -> 欠損 | AQ15: =IF(A15="","",IF(ISNUMBER(SEARCH("2歳",Z15)),"2歳戦",IF(ISNUMBER(SEARCH("3歳未勝利",Z15)),"3歳未勝利",IF(ISNUMBER(SEARCH("未勝利",Z15)),"その他未勝利",IF(ISNUMBER(SEARCH("G1",Z15)),"G1",IF(ISNUMBER(SEARCH("G2",Z15)),"G2",IF(ISNUMBER(SEARCH("G3",Z15)),"G3",IF(ISNUMBER(SEARCH("古馬条件",Z15)),"古馬条件戦",IF(ISNUMBER(SEARCH("重賞",Z15)),"重賞","分類不能"))))))))) -> 分類不能 | AS15: 11 | AT15: 2歳 | AU15: A1 | AV15: 新馬 | AY15: 1 | AZ15: 芝 | BA15: 1400 | BB15: 11 | BC15: 良 | BD15: 002 | BE15: 指定なし | BF15: 0 | BG15: 3 | BH15: 馬齢 | BI15: 13 | BJ15: 2 | BK15: 左 | BL15: 1 | BM15: 通常(内) | BN15: 1 | BO15: A | BP15: 2 | BQ15: =IF(A15="","",AT15) -> 2歳 | BR15: =IF(A15="","",IF(BA15<=1200,"～1200",IF(BA15<=1500,"1300～1500",IF(BA15=1600,"1600",IF(BA15<=1800,"1700～1800",IF(BA15<=2000,"1900～2000","2100以上")))))) -> 1300～1500 | BS15: =IF(A15="","",IF(AX15="G1","G1",IF(AX15="G2","G2",IF(AX15="G3","G3",IF(AX15="L","L","その他"))))) -> その他 | BT15: =IF(A15="","",IF(BI15="","未結合",IF(D15=BI15,"一致","不一致"))) -> 一致 | BU15: =IF(A15="","",IF(BE15="牝馬限定","牝馬限定","その他")) -> その他
A16: 46228 | B16: 中京 | C16: 3 | D16: 12 | E16: 6 | F16: コスモフィレンツェ | G16: 67 | H16: 2 | I16: レッドブライトン | J16: 58 | K16: 10 | L16: プレスバーン | M16: 58 | N16: =IF(A16="","",G16-J16) -> 9 | O16: =IF(A16="","",J16-M16) -> 0 | P16: =IF(A16="","",G16+J16) -> 125 | Q16: =IF(A16="","",IF(AND(Y16<>"参考",G16>=ルール設定!$B$2),"○","")) | R16: =IF(A16="","",IF(AND(Y16<>"参考",G16>=ルール設定!$B$3,N16>=ルール設定!$B$4),"○","")) | S16: =IF(A16="","",IF(AND(Y16<>"参考",G16>=ルール設定!$B$5,J16>=ルール設定!$B$6,O16>=ルール設定!$B$7),"○","")) | T16: 2 | U16: 4 | V16: =IF(A16="","",IF(AND(ISNUMBER(T16),ISNUMBER(U16)),IF(AND(T16<=3,U16<=3),"○","×"),"")) -> × | W16: 130 | Y16: 事後発見 | Z16: 同率は馬番順で上位3頭欄へ | AI16: 9 | AJ16: 60～69 | AK16: 5～9 | AL16: 0～9 | AM16: 120～139 | AN16: 12～14 | AO16: =IF(A16="","",IF(COUNTIFS(全馬データ!$A$2:$A$50000,A16,全馬データ!$B$2:$B$50000,B16,全馬データ!$C$2:$C$50000,C16,全馬データ!$D$2:$D$50000,E16,全馬データ!$K$2:$K$50000,"<>")=0,"",SUMIFS(全馬データ!$K$2:$K$50000,全馬データ!$A$2:$A$50000,A16,全馬データ!$B$2:$B$50000,B16,全馬データ!$C$2:$C$50000,C16,全馬データ!$D$2:$D$50000,E16))) | AP16: =IF(A16="","",IF(AO16="","欠損",IF(AO16<=1.1,"1.0～1.1",IF(AO16<1.3,"1.2",IF(AO16<1.5,"1.3～1.4",IF(AO16<2,"1.5～1.9","2.0以上")))))) -> 欠損 | AQ16: =IF(A16="","",IF(ISNUMBER(SEARCH("2歳",Z16)),"2歳戦",IF(ISNUMBER(SEARCH("3歳未勝利",Z16)),"3歳未勝利",IF(ISNUMBER(SEARCH("未勝利",Z16)),"その他未勝利",IF(ISNUMBER(SEARCH("G1",Z16)),"G1",IF(ISNUMBER(SEARCH("G2",Z16)),"G2",IF(ISNUMBER(SEARCH("G3",Z16)),"G3",IF(ISNUMBER(SEARCH("古馬条件",Z16)),"古馬条件戦",IF(ISNUMBER(SEARCH("重賞",Z16)),"重賞","分類不能"))))))))) -> 分類不能 | AS16: 12 | AT16: 3歳 | AU16: A3 | AV16: 未勝利 | AY16: 1 | AZ16: 芝 | BA16: 2000 | BB16: 11 | BC16: 良 | BD16: 002 | BE16: 指定なし | BF16: 0 | BG16: 3 | BH16: 馬齢 | BI16: 12 | BJ16: 2 | BK16: 左 | BL16: 1 | BM16: 通常(内) | BN16: 1 | BO16: A | BP16: 2 | BQ16: =IF(A16="","",AT16) -> 3歳 | BR16: =IF(A16="","",IF(BA16<=1200,"～1200",IF(BA16<=1500,"1300～1500",IF(BA16=1600,"1600",IF(BA16<=1800,"1700～1800",IF(BA16<=2000,"1900～2000","2100以上")))))) -> 1900～2000 | BS16: =IF(A16="","",IF(AX16="G1","G1",IF(AX16="G2","G2",IF(AX16="G3","G3",IF(AX16="L","L","その他"))))) -> その他 | BT16: =IF(A16="","",IF(BI16="","未結合",IF(D16=BI16,"一致","不一致"))) -> 一致 | BU16: =IF(A16="","",IF(BE16="牝馬限定","牝馬限定","その他")) -> その他
A17: 46228 | B17: 中京 | C17: 4 | D17: 16 | E17: 14 | F17: タロ | G17: 62 | H17: 2 | I17: ベルアズーロ | J17: 58 | K17: 8 | L17: ナウオアネヴァー | M17: 37 | N17: =IF(A17="","",G17-J17) -> 4 | O17: =IF(A17="","",J17-M17) -> 21 | P17: =IF(A17="","",G17+J17) -> 120 | Q17: =IF(A17="","",IF(AND(Y17<>"参考",G17>=ルール設定!$B$2),"○","")) | R17: =IF(A17="","",IF(AND(Y17<>"参考",G17>=ルール設定!$B$3,N17>=ルール設定!$B$4),"○","")) | S17: =IF(A17="","",IF(AND(Y17<>"参考",G17>=ルール設定!$B$5,J17>=ルール設定!$B$6,O17>=ルール設定!$B$7),"○","")) -> ○ | T17: 2 | U17: 4 | V17: =IF(A17="","",IF(AND(ISNUMBER(T17),ISNUMBER(U17)),IF(AND(T17<=3,U17<=3),"○","×"),"")) -> × | W17: 200 | Y17: 事後発見 | AI17: 25 | AJ17: 60～69 | AK17: 0～4 | AL17: 20～29 | AM17: 120～139 | AN17: 15以上 | AO17: =IF(A17="","",IF(COUNTIFS(全馬データ!$A$2:$A$50000,A17,全馬データ!$B$2:$B$50000,B17,全馬データ!$C$2:$C$50000,C17,全馬データ!$D$2:$D$50000,E17,全馬データ!$K$2:$K$50000,"<>")=0,"",SUMIFS(全馬データ!$K$2:$K$50000,全馬データ!$A$2:$A$50000,A17,全馬データ!$B$2:$B$50000,B17,全馬データ!$C$2:$C$50000,C17,全馬データ!$D$2:$D$50000,E17))) | AP17: =IF(A17="","",IF(AO17="","欠損",IF(AO17<=1.1,"1.0～1.1",IF(AO17<1.3,"1.2",IF(AO17<1.5,"1.3～1.4",IF(AO17<2,"1.5～1.9","2.0以上")))))) -> 欠損 | AQ17: =IF(A17="","",IF(ISNUMBER(SEARCH("2歳",Z17)),"2歳戦",IF(ISNUMBER(SEARCH("3歳未勝利",Z17)),"3歳未勝利",IF(ISNUMBER(SEARCH("未勝利",Z17)),"その他未勝利",IF(ISNUMBER(SEARCH("G1",Z17)),"G1",IF(ISNUMBER(SEARCH("G2",Z17)),"G2",IF(ISNUMBER(SEARCH("G3",Z17)),"G3",IF(ISNUMBER(SEARCH("古馬条件",Z17)),"古馬条件戦",IF(ISNUMBER(SEARCH("重賞",Z17)),"重賞","分類不能"))))))))) -> 分類不能 | AS17: 12 | AT17: 3歳 | AU17: A3 | AV17: 未勝利 | AY17: 2 | AZ17: ダート | BA17: 1800 | BB17: 10 | BC17: 良 | BD17: 002 | BE17: 指定なし | BF17: 0 | BG17: 3 | BH17: 馬齢 | BI17: 16 | BJ17: 2 | BK17: 左 | BL17: 1 | BM17: 通常(内) | BP17: 2 | BQ17: =IF(A17="","",AT17) -> 3歳 | BR17: =IF(A17="","",IF(BA17<=1200,"～1200",IF(BA17<=1500,"1300～1500",IF(BA17=1600,"1600",IF(BA17<=1800,"1700～1800",IF(BA17<=2000,"1900～2000","2100以上")))))) -> 1700～1800 | BS17: =IF(A17="","",IF(AX17="G1","G1",IF(AX17="G2","G2",IF(AX17="G3","G3",IF(AX17="L","L","その他"))))) -> その他 | BT17: =IF(A17="","",IF(BI17="","未結合",IF(D17=BI17,"一致","不一致"))) -> 一致 | BU17: =IF(A17="","",IF(BE17="牝馬限定","牝馬限定","その他")) -> その他
A18: 46228 | B18: 中京 | C18: 5 | D18: 16 | E18: 11 | F18: セルヴァジオ1 | G18: 56 | H18: 5 | I18: セコンドトゥベスト | J18: 47 | K18: 12 | L18: ファルカータ | M18: 41 | N18: =IF(A18="","",G18-J18) -> 9 | O18: =IF(A18="","",J18-M18) -> 6 | P18: =IF(A18="","",G18+J18) -> 103 | Q18: =IF(A18="","",IF(AND(Y18<>"参考",G18>=ルール設定!$B$2),"○","")) | R18: =IF(A18="","",IF(AND(Y18<>"参考",G18>=ルール設定!$B$3,N18>=ルール設定!$B$4),"○","")) | S18: =IF(A18="","",IF(AND(Y18<>"参考",G18>=ルール設定!$B$5,J18>=ルール設定!$B$6,O18>=ルール設定!$B$7),"○","")) | T18: 4 | U18: 4 | V18: =IF(A18="","",IF(AND(ISNUMBER(T18),ISNUMBER(U18)),IF(AND(T18<=3,U18<=3),"○","×"),"")) -> × | Y18: 事後発見 | AI18: 15 | AJ18: ～59 | AK18: 5～9 | AL18: 10～19 | AM18: 100～119 | AN18: 15以上 | AO18: =IF(A18="","",IF(COUNTIFS(全馬データ!$A$2:$A$50000,A18,全馬データ!$B$2:$B$50000,B18,全馬データ!$C$2:$C$50000,C18,全馬データ!$D$2:$D$50000,E18,全馬データ!$K$2:$K$50000,"<>")=0,"",SUMIFS(全馬データ!$K$2:$K$50000,全馬データ!$A$2:$A$50000,A18,全馬データ!$B$2:$B$50000,B18,全馬データ!$C$2:$C$50000,C18,全馬データ!$D$2:$D$50000,E18))) | AP18: =IF(A18="","",IF(AO18="","欠損",IF(AO18<=1.1,"1.0～1.1",IF(AO18<1.3,"1.2",IF(AO18<1.5,"1.3～1.4",IF(AO18<2,"1.5～1.9","2.0以上")))))) -> 欠損 | AQ18: =IF(A18="","",IF(ISNUMBER(SEARCH("2歳",Z18)),"2歳戦",IF(ISNUMBER(SEARCH("3歳未勝利",Z18)),"3歳未勝利",IF(ISNUMBER(SEARCH("未勝利",Z18)),"その他未勝利",IF(ISNUMBER(SEARCH("G1",Z18)),"G1",IF(ISNUMBER(SEARCH("G2",Z18)),"G2",IF(ISNUMBER(SEARCH("G3",Z18)),"G3",IF(ISNUMBER(SEARCH("古馬条件",Z18)),"古馬条件戦",IF(ISNUMBER(SEARCH("重賞",Z18)),"重賞","分類不能"))))))))) -> 分類不能 | AS18: 12 | AT18: 3歳 | AU18: A3 | AV18: 未勝利 | AY18: 1 | AZ18: 芝 | BA18: 1600 | BB18: 11 | BC18: 良 | BD18: 022 | BE18: 牝馬限定 | BF18: 1 | BG18: 3 | BH18: 馬齢 | BI18: 16 | BJ18: 2 | BK18: 左 | BL18: 1 | BM18: 通常(内) | BN18: 1 | BO18: A | BP18: 2 | BQ18: =IF(A18="","",AT18) -> 3歳 | BR18: =IF(A18="","",IF(BA18<=1200,"～1200",IF(BA18<=1500,"1300～1500",IF(BA18=1600,"1600",IF(BA18<=1800,"1700～1800",IF(BA18<=2000,"1900～2000","2100以上")))))) -> 1600 | BS18: =IF(A18="","",IF(AX18="G1","G1",IF(AX18="G2","G2",IF(AX18="G3","G3",IF(AX18="L","L","その他"))))) -> その他 | BT18: =IF(A18="","",IF(BI18="","未結合",IF(D18=BI18,"一致","不一致"))) -> 一致 | BU18: =IF(A18="","",IF(BE18="牝馬限定","牝馬限定","その他")) -> 牝馬限定
A19: 46228 | B19: 中京 | C19: 6 | D19: 16 | E19: 9 | F19: ポートデラメール | G19: 58 | H19: 12 | I19: エブリーポッシブル | J19: 47 | K19: 6 | L19: ゼロヴィジビリティ | M19: 39 | N19: =IF(A19="","",G19-J19) -> 11 | O19: =IF(A19="","",J19-M19) -> 8 | P19: =IF(A19="","",G19+J19) -> 105 | Q19: =IF(A19="","",IF(AND(Y19<>"参考",G19>=ルール設定!$B$2),"○","")) | R19: =IF(A19="","",IF(AND(Y19<>"参考",G19>=ルール設定!$B$3,N19>=ルール設定!$B$4),"○","")) | S19: =IF(A19="","",IF(AND(Y19<>"参考",G19>=ルール設定!$B$5,J19>=ルール設定!$B$6,O19>=ルール設定!$B$7),"○","")) | T19: 4 | U19: 1 | V19: =IF(A19="","",IF(AND(ISNUMBER(T19),ISNUMBER(U19)),IF(AND(T19<=3,U19<=3),"○","×"),"")) -> × | Y19: 事後発見 | Z19: 同率は馬番順で上位3頭欄へ | AI19: 19 | AJ19: ～59 | AK19: 10～19 | AL19: 10～19 | AM19: 100～119 | AN19: 15以上 | AO19: =IF(A19="","",IF(COUNTIFS(全馬データ!$A$2:$A$50000,A19,全馬データ!$B$2:$B$50000,B19,全馬データ!$C$2:$C$50000,C19,全馬データ!$D$2:$D$50000,E19,全馬データ!$K$2:$K$50000,"<>")=0,"",SUMIFS(全馬データ!$K$2:$K$50000,全馬データ!$A$2:$A$50000,A19,全馬データ!$B$2:$B$50000,B19,全馬データ!$C$2:$C$50000,C19,全馬データ!$D$2:$D$50000,E19))) | AP19: =IF(A19="","",IF(AO19="","欠損",IF(AO19<=1.1,"1.0～1.1",IF(AO19<1.3,"1.2",IF(AO19<1.5,"1.3～1.4",IF(AO19<2,"1.5～1.9","2.0以上")))))) -> 欠損 | AQ19: =IF(A19="","",IF(ISNUMBER(SEARCH("2歳",Z19)),"2歳戦",IF(ISNUMBER(SEARCH("3歳未勝利",Z19)),"3歳未勝利",IF(ISNUMBER(SEARCH("未勝利",Z19)),"その他未勝利",IF(ISNUMBER(SEARCH("G1",Z19)),"G1",IF(ISNUMBER(SEARCH("G2",Z19)),"G2",IF(ISNUMBER(SEARCH("G3",Z19)),"G3",IF(ISNUMBER(SEARCH("古馬条件",Z19)),"古馬条件戦",IF(ISNUMBER(SEARCH("重賞",Z19)),"重賞","分類不能"))))))))) -> 分類不能 | AR19: 四日市特別 | AS19: 13 | AT19: 3歳以上 | AU19: 10 | AV19: 2勝クラス | AW19: 5 | AX19: 特別 | AY19: 2 | AZ19: ダート | BA19: 1400 | BB19: 10 | BC19: 良 | BD19: 102 | BE19: 指定なし | BF19: 0 | BG19: 4 | BH19: 定量 | BI19: 16 | BJ19: 2 | BK19: 左 | BL19: 1 | BM19: 通常(内) | BP19: 2 | BQ19: =IF(A19="","",AT19) -> 3歳以上 | BR19: =IF(A19="","",IF(BA19<=1200,"～1200",IF(BA19<=1500,"1300～1500",IF(BA19=1600,"1600",IF(BA19<=1800,"1700～1800",IF(BA19<=2000,"1900～2000","2100以上")))))) -> 1300～1500 | BS19: =IF(A19="","",IF(AX19="G1","G1",IF(AX19="G2","G2",IF(AX19="G3","G3",IF(AX19="L","L","その他"))))) -> その他 | BT19: =IF(A19="","",IF(BI19="","未結合",IF(D19=BI19,"一致","不一致"))) -> 一致 | BU19: =IF(A19="","",IF(BE19="牝馬限定","牝馬限定","その他")) -> その他
A20: 46228 | B20: 中京 | C20: 7 | D20: 11 | E20: 7 | F20: ハーツコンチェルト | G20: 60 | H20: 9 | I20: ミュージシャン | J20: 58 | K20: 1 | L20: ミッキーゴールド | M20: 44 | N20: =IF(A20="","",G20-J20) -> 2 | O20: =IF(A20="","",J20-M20) -> 14 | P20: =IF(A20="","",G20+J20) -> 118 | Q20: =IF(A20="","",IF(AND(Y20<>"参考",G20>=ルール設定!$B$2),"○","")) | R20: =IF(A20="","",IF(AND(Y20<>"参考",G20>=ルール設定!$B$3,N20>=ルール設定!$B$4),"○","")) | S20: =IF(A20="","",IF(AND(Y20<>"参考",G20>=ルール設定!$B$5,J20>=ルール設定!$B$6,O20>=ルール設定!$B$7),"○","")) | T20: 3 | U20: 4 | V20: =IF(A20="","",IF(AND(ISNUMBER(T20),ISNUMBER(U20)),IF(AND(T20<=3,U20<=3),"○","×"),"")) -> × | W20: 170 | Y20: 事後発見 | AI20: 16 | AJ20: 60～69 | AK20: 0～4 | AL20: 10～19 | AM20: 100～119 | AN20: 8～11 | AO20: =IF(A20="","",IF(COUNTIFS(全馬データ!$A$2:$A$50000,A20,全馬データ!$B$2:$B$50000,B20,全馬データ!$C$2:$C$50000,C20,全馬データ!$D$2:$D$50000,E20,全馬データ!$K$2:$K$50000,"<>")=0,"",SUMIFS(全馬データ!$K$2:$K$50000,全馬データ!$A$2:$A$50000,A20,全馬データ!$B$2:$B$50000,B20,全馬データ!$C$2:$C$50000,C20,全馬データ!$D$2:$D$50000,E20))) | AP20: =IF(A20="","",IF(AO20="","欠損",IF(AO20<=1.1,"1.0～1.1",IF(AO20<1.3,"1.2",IF(AO20<1.5,"1.3～1.4",IF(AO20<2,"1.5～1.9","2.0以上")))))) -> 欠損 | AQ20: =IF(A20="","",IF(ISNUMBER(SEARCH("2歳",Z20)),"2歳戦",IF(ISNUMBER(SEARCH("3歳未勝利",Z20)),"3歳未勝利",IF(ISNUMBER(SEARCH("未勝利",Z20)),"その他未勝利",IF(ISNUMBER(SEARCH("G1",Z20)),"G1",IF(ISNUMBER(SEARCH("G2",Z20)),"G2",IF(ISNUMBER(SEARCH("G3",Z20)),"G3",IF(ISNUMBER(SEARCH("古馬条件",Z20)),"古馬条件戦",IF(ISNUMBER(SEARCH("重賞",Z20)),"重賞","分類不能"))))))))) -> 分類不能 | AR20: 関ケ原ステークス | AS20: 13 | AT20: 3歳以上 | AU20: 16 | AV20: 3勝クラス | AW20: 5 | AX20: 特別 | AY20: 1 | AZ20: 芝 | BA20: 2200 | BB20: 11 | BC20: 良 | BD20: 103 | BE20: 指定なし | BF20: 0 | BG20: 4 | BH20: 定量 | BI20: 11 | BJ20: 2 | BK20: 左 | BL20: 1 | BM20: 通常(内) | BN20: 1 | BO20: A | BP20: 2 | BQ20: =IF(A20="","",AT20) -> 3歳以上 | BR20: =IF(A20="","",IF(BA20<=1200,"～1200",IF(BA20<=1500,"1300～1500",IF(BA20=1600,"1600",IF(BA20<=1800,"1700～1800",IF(BA20<=2000,"1900～2000","2100以上")))))) -> 2100以上 | BS20: =IF(A20="","",IF(AX20="G1","G1",IF(AX20="G2","G2",IF(AX20="G3","G3",IF(AX20="L","L","その他"))))) -> その他 | BT20: =IF(A20="","",IF(BI20="","未結合",IF(D20=BI20,"一致","不一致"))) -> 一致 | BU20: =IF(A20="","",IF(BE20="牝馬限定","牝馬限定","その他")) -> その他
A21: 46228 | B21: 中京 | C21: 8 | D21: 8 | E21: 2 | F21: サラコスティ | G21: 74 | H21: 1 | I21: スノースケープ | J21: 60 | K21: 5 | L21: ブラックシャリマー | M21: 52 | N21: =IF(A21="","",G21-J21) -> 14 | O21: =IF(A21="","",J21-M21) -> 8 | P21: =IF(A21="","",G21+J21) -> 134 | Q21: =IF(A21="","",IF(AND(Y21<>"参考",G21>=ルール設定!$B$2),"○","")) | R21: =IF(A21="","",IF(AND(Y21<>"参考",G21>=ルール設定!$B$3,N21>=ルール設定!$B$4),"○","")) | S21: =IF(A21="","",IF(AND(Y21<>"参考",G21>=ルール設定!$B$5,J21>=ルール設定!$B$6,O21>=ルール設定!$B$7),"○","")) | T21: 3 | U21: 2 | V21: =IF(A21="","",IF(AND(ISNUMBER(T21),ISNUMBER(U21)),IF(AND(T21<=3,U21<=3),"○","×"),"")) -> ○ | W21: 210 | X21: 440 | Y21: 事後発見 | AI21: 22 | AJ21: 70～74 | AK21: 10～19 | AL21: 20～29 | AM21: 120～139 | AN21: 8～11 | AO21: =IF(A21="","",IF(COUNTIFS(全馬データ!$A$2:$A$50000,A21,全馬データ!$B$2:$B$50000,B21,全馬データ!$C$2:$C$50000,C21,全馬データ!$D$2:$D$50000,E21,全馬データ!$K$2:$K$50000,"<>")=0,"",SUMIFS(全馬データ!$K$2:$K$50000,全馬データ!$A$2:$A$50000,A21,全馬データ!$B$2:$B$50000,B21,全馬データ!$C$2:$C$50000,C21,全馬データ!$D$2:$D$50000,E21))) | AP21: =IF(A21="","",IF(AO21="","欠損",IF(AO21<=1.1,"1.0～1.1",IF(AO21<1.3,"1.2",IF(AO21<1.5,"1.3～1.4",IF(AO21<2,"1.5～1.9","2.0以上")))))) -> 欠損 | AQ21: =IF(A21="","",IF(ISNUMBER(SEARCH("2歳",Z21)),"2歳戦",IF(ISNUMBER(SEARCH("3歳未勝利",Z21)),"3歳未勝利",IF(ISNUMBER(SEARCH("未勝利",Z21)),"その他未勝利",IF(ISNUMBER(SEARCH("G1",Z21)),"G1",IF(ISNUMBER(SEARCH("G2",Z21)),"G2",IF(ISNUMBER(SEARCH("G3",Z21)),"G3",IF(ISNUMBER(SEARCH("古馬条件",Z21)),"古馬条件戦",IF(ISNUMBER(SEARCH("重賞",Z21)),"重賞","分類不能"))))))))) -> 分類不能 | AR21: 香嵐渓特別 | AS21: 13 | AT21: 3歳以上 | AU21: 05 | AV21: 1勝クラス | AW21: 5 | AX21: 特別 | AY21: 1 | AZ21: 芝 | BA21: 2000 | BB21: 11 | BC21: 良 | BD21: 102 | BE21: 指定なし | BF21: 0 | BG21: 4 | BH21: 定量 | BI21: 8 | BJ21: 2 | BK21: 左 | BL21: 1 | BM21: 通常(内) | BN21: 1 | BO21: A | BP21: 2 | BQ21: =IF(A21="","",AT21) -> 3歳以上 | BR21: =IF(A21="","",IF(BA21<=1200,"～1200",IF(BA21<=1500,"1300～1500",IF(BA21=1600,"1600",IF(BA21<=1800,"1700～1800",IF(BA21<=2000,"1900～2000","2100以上")))))) -> 1900～2000 | BS21: =IF(A21="","",IF(AX21="G1","G1",IF(AX21="G2","G2",IF(AX21="G3","G3",IF(AX21="L","L","その他"))))) -> その他 | BT21: =IF(A21="","",IF(BI21="","未結合",IF(D21=BI21,"一致","不一致"))) -> 一致 | BU21: =IF(A21="","",IF(BE21="牝馬限定","牝馬限定","その他")) -> その他
A22: 46228 | B22: 中京 | C22: 9 | D22: 16 | E22: 2 | F22: ルビドゥソレイユ | G22: 60 | H22: 1 | I22: ワイズギャング | J22: 44 | K22: 14 | L22: イーブンベター | M22: 37 | N22: =IF(A22="","",G22-J22) -> 16 | O22: =IF(A22="","",J22-M22) -> 7 | P22: =IF(A22="","",G22+J22) -> 104 | Q22: =IF(A22="","",IF(AND(Y22<>"参考",G22>=ルール設定!$B$2),"○","")) | R22: =IF(A22="","",IF(AND(Y22<>"参考",G22>=ルール設定!$B$3,N22>=ルール設定!$B$4),"○","")) | S22: =IF(A22="","",IF(AND(Y22<>"参考",G22>=ルール設定!$B$5,J22>=ルール設定!$B$6,O22>=ルール設定!$B$7),"○","")) | T22: 1 | U22: 4 | V22: =IF(A22="","",IF(AND(ISNUMBER(T22),ISNUMBER(U22)),IF(AND(T22<=3,U22<=3),"○","×"),"")) -> × | W22: 150 | Y22: 事後発見 | AI22: 23 | AJ22: 60～69 | AK22: 10～19 | AL22: 20～29 | AM22: 100～119 | AN22: 15以上 | AO22: =IF(A22="","",IF(COUNTIFS(全馬データ!$A$2:$A$50000,A22,全馬データ!$B$2:$B$50000,B22,全馬データ!$C$2:$C$50000,C22,全馬データ!$D$2:$D$50000,E22,全馬データ!$K$2:$K$50000,"<>")=0,"",SUMIFS(全馬データ!$K$2:$K$50000,全馬データ!$A$2:$A$50000,A22,全馬データ!$B$2:$B$50000,B22,全馬データ!$C$2:$C$50000,C22,全馬データ!$D$2:$D$50000,E22))) | AP22: =IF(A22="","",IF(AO22="","欠損",IF(AO22<=1.1,"1.0～1.1",IF(AO22<1.3,"1.2",IF(AO22<1.5,"1.3～1.4",IF(AO22<2,"1.5～1.9","2.0以上")))))) -> 欠損 | AQ22: =IF(A22="","",IF(ISNUMBER(SEARCH("2歳",Z22)),"2歳戦",IF(ISNUMBER(SEARCH("3歳未勝利",Z22)),"3歳未勝利",IF(ISNUMBER(SEARCH("未勝利",Z22)),"その他未勝利",IF(ISNUMBER(SEARCH("G1",Z22)),"G1",IF(ISNUMBER(SEARCH("G2",Z22)),"G2",IF(ISNUMBER(SEARCH("G3",Z22)),"G3",IF(ISNUMBER(SEARCH("古馬条件",Z22)),"古馬条件戦",IF(ISNUMBER(SEARCH("重賞",Z22)),"重賞","分類不能"))))))))) -> 分類不能 | AS22: 13 | AT22: 3歳以上 | AU22: 05 | AV22: 1勝クラス | AY22: 2 | AZ22: ダート | BA22: 1400 | BB22: 10 | BC22: 良 | BD22: 022 | BE22: 牝馬限定 | BF22: 1 | BG22: 4 | BH22: 定量 | BI22: 16 | BJ22: 2 | BK22: 左 | BL22: 1 | BM22: 通常(内) | BP22: 2 | BQ22: =IF(A22="","",AT22) -> 3歳以上 | BR22: =IF(A22="","",IF(BA22<=1200,"～1200",IF(BA22<=1500,"1300～1500",IF(BA22=1600,"1600",IF(BA22<=1800,"1700～1800",IF(BA22<=2000,"1900～2000","2100以上")))))) -> 1300～1500 | BS22: =IF(A22="","",IF(AX22="G1","G1",IF(AX22="G2","G2",IF(AX22="G3","G3",IF(AX22="L","L","その他"))))) -> その他 | BT22: =IF(A22="","",IF(BI22="","未結合",IF(D22=BI22,"一致","不一致"))) -> 一致 | BU22: =IF(A22="","",IF(BE22="牝馬限定","牝馬限定","その他")) -> 牝馬限定
A23: 46228 | B23: 中京 | C23: 10 | D23: 13 | E23: 9 | F23: アスクチャンスマン | G23: 71 | H23: 12 | I23: リヒトミューレ | J23: 47 | K23: 1 | L23: ミランド | M23: 41 | N23: =IF(A23="","",G23-J23) -> 24 | O23: =IF(A23="","",J23-M23) -> 6 | P23: =IF(A23="","",G23+J23) -> 118 | Q23: =IF(A23="","",IF(AND(Y23<>"参考",G23>=ルール設定!$B$2),"○","")) | R23: =IF(A23="","",IF(AND(Y23<>"参考",G23>=ルール設定!$B$3,N23>=ルール設定!$B$4),"○","")) | S23: =IF(A23="","",IF(AND(Y23<>"参考",G23>=ルール設定!$B$5,J23>=ルール設定!$B$6,O23>=ルール設定!$B$7),"○","")) | T23: 3 | U23: 1 | V23: =IF(A23="","",IF(AND(ISNUMBER(T23),ISNUMBER(U23)),IF(AND(T23<=3,U23<=3),"○","×"),"")) -> ○ | W23: 130 | X23: 310 | Y23: 事後発見 | Z23: 同率は馬番順で上位3頭欄へ | AI23: 30 | AJ23: 70～74 | AK23: 20～29 | AL23: 30～39 | AM23: 100～119 | AN23: 12～14 | AO23: =IF(A23="","",IF(COUNTIFS(全馬データ!$A$2:$A$50000,A23,全馬データ!$B$2:$B$50000,B23,全馬データ!$C$2:$C$50000,C23,全馬データ!$D$2:$D$50000,E23,全馬データ!$K$2:$K$50000,"<>")=0,"",SUMIFS(全馬データ!$K$2:$K$50000,全馬データ!$A$2:$A$50000,A23,全馬データ!$B$2:$B$50000,B23,全馬データ!$C$2:$C$50000,C23,全馬データ!$D$2:$D$50000,E23))) | AP23: =IF(A23="","",IF(AO23="","欠損",IF(AO23<=1.1,"1.0～1.1",IF(AO23<1.3,"1.2",IF(AO23<1.5,"1.3～1.4",IF(AO23<2,"1.5～1.9","2.0以上")))))) -> 欠損 | AQ23: =IF(A23="","",IF(ISNUMBER(SEARCH("2歳",Z23)),"2歳戦",IF(ISNUMBER(SEARCH("3歳未勝利",Z23)),"3歳未勝利",IF(ISNUMBER(SEARCH("未勝利",Z23)),"その他未勝利",IF(ISNUMBER(SEARCH("G1",Z23)),"G1",IF(ISNUMBER(SEARCH("G2",Z23)),"G2",IF(ISNUMBER(SEARCH("G3",Z23)),"G3",IF(ISNUMBER(SEARCH("古馬条件",Z23)),"古馬条件戦",IF(ISNUMBER(SEARCH("重賞",Z23)),"重賞","分類不能"))))))))) -> 分類不能 | AS23: 13 | AT23: 3歳以上 | AU23: 05 | AV23: 1勝クラス | AY23: 2 | AZ23: ダート | BA23: 1800 | BB23: 10 | BC23: 良 | BD23: 002 | BE23: 指定なし | BF23: 0 | BG23: 4 | BH23: 定量 | BI23: 13 | BJ23: 2 | BK23: 左 | BL23: 1 | BM23: 通常(内) | BP23: 2 | BQ23: =IF(A23="","",AT23) -> 3歳以上 | BR23: =IF(A23="","",IF(BA23<=1200,"～1200",IF(BA23<=1500,"1300～1500",IF(BA23=1600,"1600",IF(BA23<=1800,"1700～1800",IF(BA23<=2000,"1900～2000","2100以上")))))) -> 1700～1800 | BS23: =IF(A23="","",IF(AX23="G1","G1",IF(AX23="G2","G2",IF(AX23="G3","G3",IF(AX23="L","L","その他"))))) -> その他 | BT23: =IF(A23="","",IF(BI23="","未結合",IF(D23=BI23,"一致","不一致"))) -> 一致 | BU23: =IF(A23="","",IF(BE23="牝馬限定","牝馬限定","その他")) -> その他
A24: 46228 | B24: 中京 | C24: 11 | D24: 8 | E24: 3 | F24: ルージュスプリヤ | G24: 65 | H24: 7 | I24: ケールハイム | J24: 60 | K24: 5 | L24: ニシノトリビュート | M24: 34 | N24: =IF(A24="","",G24-J24) -> 5 | O24: =IF(A24="","",J24-M24) -> 26 | P24: =IF(A24="","",G24+J24) -> 125 | Q24: =IF(A24="","",IF(AND(Y24<>"参考",G24>=ルール設定!$B$2),"○","")) | R24: =IF(A24="","",IF(AND(Y24<>"参考",G24>=ルール設定!$B$3,N24>=ルール設定!$B$4),"○","")) | S24: =IF(A24="","",IF(AND(Y24<>"参考",G24>=ルール設定!$B$5,J24>=ルール設定!$B$6,O24>=ルール設定!$B$7),"○","")) -> ○ | T24: 1 | U24: 2 | V24: =IF(A24="","",IF(AND(ISNUMBER(T24),ISNUMBER(U24)),IF(AND(T24<=3,U24<=3),"○","×"),"")) -> ○ | W24: 110 | X24: 130 | Y24: 事後発見 | AI24: 31 | AJ24: 60～69 | AK24: 5～9 | AL24: 30～39 | AM24: 120～139 | AN24: 8～11 | AO24: =IF(A24="","",IF(COUNTIFS(全馬データ!$A$2:$A$50000,A24,全馬データ!$B$2:$B$50000,B24,全馬データ!$C$2:$C$50000,C24,全馬データ!$D$2:$D$50000,E24,全馬データ!$K$2:$K$50000,"<>")=0,"",SUMIFS(全馬データ!$K$2:$K$50000,全馬データ!$A$2:$A$50000,A24,全馬データ!$B$2:$B$50000,B24,全馬データ!$C$2:$C$50000,C24,全馬データ!$D$2:$D$50000,E24))) | AP24: =IF(A24="","",IF(AO24="","欠損",IF(AO24<=1.1,"1.0～1.1",IF(AO24<1.3,"1.2",IF(AO24<1.5,"1.3～1.4",IF(AO24<2,"1.5～1.9","2.0以上")))))) -> 欠損 | AQ24: =IF(A24="","",IF(ISNUMBER(SEARCH("2歳",Z24)),"2歳戦",IF(ISNUMBER(SEARCH("3歳未勝利",Z24)),"3歳未勝利",IF(ISNUMBER(SEARCH("未勝利",Z24)),"その他未勝利",IF(ISNUMBER(SEARCH("G1",Z24)),"G1",IF(ISNUMBER(SEARCH("G2",Z24)),"G2",IF(ISNUMBER(SEARCH("G3",Z24)),"G3",IF(ISNUMBER(SEARCH("古馬条件",Z24)),"古馬条件戦",IF(ISNUMBER(SEARCH("重賞",Z24)),"重賞","分類不能"))))))))) -> 分類不能 | AS24: 13 | AT24: 3歳以上 | AU24: 05 | AV24: 1勝クラス | AY24: 1 | AZ24: 芝 | BA24: 1200 | BB24: 11 | BC24: 良 | BD24: 002 | BE24: 指定なし | BF24: 0 | BG24: 4 | BH24: 定量 | BI24: 8 | BJ24: 2 | BK24: 左 | BL24: 1 | BM24: 通常(内) | BN24: 1 | BO24: A | BP24: 2 | BQ24: =IF(A24="","",AT24) -> 3歳以上 | BR24: =IF(A24="","",IF(BA24<=1200,"～1200",IF(BA24<=1500,"1300～1500",IF(BA24=1600,"1600",IF(BA24<=1800,"1700～1800",IF(BA24<=2000,"1900～2000","2100以上")))))) -> ～1200 | BS24: =IF(A24="","",IF(AX24="G1","G1",IF(AX24="G2","G2",IF(AX24="G3","G3",IF(AX24="L","L","その他"))))) -> その他 | BT24: =IF(A24="","",IF(BI24="","未結合",IF(D24=BI24,"一致","不一致"))) -> 一致 | BU24: =IF(A24="","",IF(BE24="牝馬限定","牝馬限定","その他")) -> その他
A25: 46228 | B25: 中京 | C25: 12 | D25: 16 | E25: 4 | F25: ビッグヒーロー | G25: 56 | H25: 13 | I25: ミッキーラヴィータ | J25: 56 | K25: 8 | L25: ララディアーブル | M25: 39 | N25: =IF(A25="","",G25-J25) -> 0 | O25: =IF(A25="","",J25-M25) -> 17 | P25: =IF(A25="","",G25+J25) -> 112 | Q25: =IF(A25="","",IF(AND(Y25<>"参考",G25>=ルール設定!$B$2),"○","")) | R25: =IF(A25="","",IF(AND(Y25<>"参考",G25>=ルール設定!$B$3,N25>=ルール設定!$B$4),"○","")) | S25: =IF(A25="","",IF(AND(Y25<>"参考",G25>=ルール設定!$B$5,J25>=ルール設定!$B$6,O25>=ルール設定!$B$7),"○","")) | T25: 2 | U25: 4 | V25: =IF(A25="","",IF(AND(ISNUMBER(T25),ISNUMBER(U25)),IF(AND(T25<=3,U25<=3),"○","×"),"")) -> × | W25: 140 | Y25: 事後発見 | Z25: 同率は馬番順で上位3頭欄へ | AI25: 17 | AJ25: ～59 | AK25: 0～4 | AL25: 10～19 | AM25: 100～119 | AN25: 15以上 | AO25: =IF(A25="","",IF(COUNTIFS(全馬データ!$A$2:$A$50000,A25,全馬データ!$B$2:$B$50000,B25,全馬データ!$C$2:$C$50000,C25,全馬データ!$D$2:$D$50000,E25,全馬データ!$K$2:$K$50000,"<>")=0,"",SUMIFS(全馬データ!$K$2:$K$50000,全馬データ!$A$2:$A$50000,A25,全馬データ!$B$2:$B$50000,B25,全馬データ!$C$2:$C$50000,C25,全馬データ!$D$2:$D$50000,E25))) | AP25: =IF(A25="","",IF(AO25="","欠損",IF(AO25<=1.1,"1.0～1.1",IF(AO25<1.3,"1.2",IF(AO25<1.5,"1.3～1.4",IF(AO25<2,"1.5～1.9","2.0以上")))))) -> 欠損 | AQ25: =IF(A25="","",IF(ISNUMBER(SEARCH("2歳",Z25)),"2歳戦",IF(ISNUMBER(SEARCH("3歳未勝利",Z25)),"3歳未勝利",IF(ISNUMBER(SEARCH("未勝利",Z25)),"その他未勝利",IF(ISNUMBER(SEARCH("G1",Z25)),"G1",IF(ISNUMBER(SEARCH("G2",Z25)),"G2",IF(ISNUMBER(SEARCH("G3",Z25)),"G3",IF(ISNUMBER(SEARCH("古馬条件",Z25)),"古馬条件戦",IF(ISNUMBER(SEARCH("重賞",Z25)),"重賞","分類不能"))))))))) -> 分類不能 | AS25: 12 | AT25: 3歳 | AU25: A3 | AV25: 未勝利 | AY25: 1 | AZ25: 芝 | BA25: 1600 | BB25: 11 | BC25: 良 | BD25: 102 | BE25: 指定なし | BF25: 0 | BG25: 3 | BH25: 馬齢 | BI25: 16 | BJ25: 2 | BK25: 左 | BL25: 1 | BM25: 通常(内) | BN25: 1 | BO25: A | BP25: 2 | BQ25: =IF(A25="","",AT25) -> 3歳 | BR25: =IF(A25="","",IF(BA25<=1200,"～1200",IF(BA25<=1500,"1300～1500",IF(BA25=1600,"1600",IF(BA25<=1800,"1700～1800",IF(BA25<=2000,"1900～2000","2100以上")))))) -> 1600 | BS25: =IF(A25="","",IF(AX25="G1","G1",IF(AX25="G2","G2",IF(AX25="G3","G3",IF(AX25="L","L","その他"))))) -> その他 | BT25: =IF(A25="","",IF(BI25="","未結合",IF(D25=BI25,"一致","不一致"))) -> 一致 | BU25: =IF(A25="","",IF(BE25="牝馬限定","牝馬限定","その他")) -> その他
